Workbook

Sheet Export Summary
B3: This document was exported from Numbers. Each table was converted to an Excel worksheet. All other objects on each Numbers sheet were placed on separate worksheets. Please be aware that formula calculations may differ in Excel.
B7: Numbers Sheet Name | C7: Numbers Table Name | D7: Excel Worksheet Name
B9: Cover
C10: Table 1 | D10: Cover
B11: Introduction
C12: Table 1 | D12: Introduction
B13: Objectives
C14: Table 1 | D14: Objectives
B15: Non-Technical Competencies
C16: Table 1 | D16: Non-Technical Competencies
B17: Overall Performance Calculation
C18: Table 1 | D18: Overall Performance Calculation
B19: Evidence
C20: Table 1 | D20: Evidence
B21: V-lookup
C22: Table 1 | D22: V-lookup

Sheet Cover
C2: إدارة الموارد البشرية
C10: نموذج تقييم الأداء
C14: الفترة الاولى من 1-1-2019 وحتى 28-2-2019
C23: إسم الموظف: | E23: ………………………………….
C25: المسمي الوظيفي : | E25: ……………….…………………
C27: الإدارة :
C29: كود الموظف : | E29: ………………………………….
C31: مستوى الوظيفة | E31: تنفيذى / اشرافى
C34: القائم بالتقييم : | E34: ...........................................
C35: المسمي الوظيفي: | E35: ...........................................
C36: فترة التقييم: | E36: ...........................................
C37: التاريخ: | E37: ...........................................

Sheet Introduction
B7: نظام تقييم الأداء
A9: لقد قامت الشركة بإنشاء نظام لتقييم الأداء يهدف إلى رفع الانتاجية وتطوير الاداء وضمان المساواة و الموضوعية في تقييم أداء الموظف لوظيفته تبعاً لمتطلبات الوظيفة ومقاييسها
A10: .المديرون مسئولون عن ضمان مراجعة و تسجيل تقييم أداء الموظف تبعا للسياسات الموضوعة
A11: إن تقييم الأداء من أفضل وسائل الإتصال التي تساعد علي إعطاء أراء و توجيهات فعالة فيما يخص أداء الموظف مقارنة بمتطلبات الوظيفة وبشكل متوازي مع إتخاذ قرارات فيما يخص الأتي:
A12: *زيادة وضوح الأدوار الوظيفية وتطوير الاداء إلى الافضل
A13: * التدريب والتطوير
A14: * (المزايا المادية)التعويضات والمكافآت
A15: * (الترقيات) التخطيط الوظيفي
A17: برجاء التكرم بتقييم أداء الموظف بعناية شديدة مع مقارنته بمتطلبات الوظيفة التي يقوم بها.

Sheet Objectives
A2: أولا / الاداء الفنى - المرتبط بالاهداف (70%)
A3: بناءاً علي الأهداف السنوية المحددة مسبقاً بين الموظف و رئيسه المباشر في بداية فترة التقييم
A4: م | B4: مؤشر الاداء | C4: معادلة القياس | D4: المستهدف للفترة | E4: الوزن النسبى | F4: الآداء الفعلى | G4: الفعلى \ المقدار | H4: ملاحظات حول البند
A5: 1 | B5: معدل المتابعات الدورية مستهدف 4 متابعات لكل بروكر شهرى ) | C5: عدد المتابعات المنفذة لكل بروكر * عدد البروكر / عدد المتابعات المخططة لكل بروكر *عدد البروكر | D5: {=7*4} -> 28 | E5: 0.1 | F5: 28 | G5: {=(F5/D5)*E5} -> 0.1 | H5: موجود 35 شركة مستهدف مارس 10 شركات تم انتظار ل3 جارى وضع الية لقياس المتابعات وتوثيقها
A6: 2 | B6: معدل تنفيذ الانشطة والزيارات الخاصة بالبروكر (مستهدف زيارة لكل بروكر شهرى ) | C6: عدد الزيارات للشركات او الانشطة المنفذة / عدد الزيارات المخططة | D6: 7 | E6: 0.2 | F6: 5 | G6: {=(F6/D6)*E6} -> 0.14285714
A7: 3 | B7: معدل الزيارات ( مستهدف 2زيارة من كل بروكر شهريا ) | C7: عدد الزيارات الفعلية /عدد الزيارات المخططة | D7: {=2*7} -> 14 | E7: 0.1 | F7: 8 | G7: {=(F7/D7)*E7} -> 0.057142857
A8: 4 | B8: معدل العقود | C8: عدد العقود / عدد الحجوزات | D8: 1 | E8: 0.05 | F8: 1 | G8: {=(F8/D8)*E8} -> 0.05 | H8: محيد
A9: 5 | B9: معدل العقود للزيارات معدل تحويل 10 % | C9: عدد العقود / اجمالى عدد الزيارات | D9: 1 | E9: 0.1 | F9: 1 | G9: {=(F9/D9)*E9} -> 0.1 | H9: محيد
A10: 6 | B10: نسبة التارجت المحقق بالجنيه مستهدف 2 عقد من القاهرة - مستهدف 2 محافظات) | C10: قيمة المحقق من المبيعات بالجنيه /جمالى المستهدف البيعى | D10: 1 | E10: 0.4 | F10: 1 | G10: {=(F10/D10)*E10} -> 0.4 | H10: محيد
A11: 7 | B11: معدل التقارير الدورية | C11: عدد التقارير المقدمة فى الوقت المخطط وبالدقة المطلوبة / عدد التقارير المخطط تقديمها ( وفقا للوقت والدقة) | D11: 3 | E11: 0.05 | F11: 3 | G11: {=(F11/D11)*E11} -> 0.05 | H11: تقرير بروكر القاهرة تقرير عرض شهر 3 تقرير زيارة المنصورة
A12: 8 | B12: معدل الالتزام بالسياسة المالية | C12: أجمالى متوسط الالتزام بالسياسة المالية لكل عقد منفذ
E15: {=SUM(E5:E14)} -> 1
A16: إجمالي النسبة النهائية | E16: {=SUM(G5:G14)} -> 0.9

Sheet Non-Technical Competencies
B2: ثانيا /الجدارات (20%)
B4: الدرجة | C4: النسبة | D4: الوصف
B5: مميز وكفء | C5: يساوى أواعلى من 100% | D5: يتجاوز أحيانًا متطلبات/الجدارات وتنطبق عليه كافة عناصر الجدارات | I5: * اعرف معنى كل تقدير من التقديرات الموجودة * اقرا كل بند من بنود كل جدارة جيدا * اعطى التقدير التذى يتناسب بدقة مع مستوى الموظف * فى حالة عدم توافر بند من بنود احد الجدارات ضع امامها علامة * اكتب بملاحظاتك حول كل جدارة إن وجدت
B6: فعال | C6: من 90% إلى 99% | D6: يفي بمتطلبات الجدارات وتنطبق عليه كافة عناصر الجدارات ولكن من الممكن الضعف فى بند موجود ولكن سلوكه يظهر دائما بشكل مرضٍ وعلى النحو المتوقع
B7: جيد | C7: من 80% إلى 89 % | D7: يقترب من تحقيق متطلبات الجدارات: ولا ينطبق عليه بندواحد او الضعف فى بندين او اكثرويحتاج إلى زيادة الجهد
B8: مقبول | C8: من 70% إلى 79% | D8: يعجز أحيانًا عن الوفاء بمتطلبات الجدارات: ولا ينطبق عليه بندين أو اكثر او الضعف فى 3 بنود جاء أداء الموظف أقل من التوقعات المتفق عليها، ولم يفى ببعض متطلبات الجدارات
B9: غير مرض | C9: من 60% إلى 69% | D9: يعجز بصفة دائمة عن الوفاء بمتطلبات الجدارات جدارات الموظف ككل غير مقبولة بوجه عام ويحتاج للتحسين الفوري. ونتيجة لذلك جاءت كل إسهاماته أقل من التوقعات بدرجة كبيرة.
B10: ضعيف | C10: أقل من 60% | D10: لا تنطبق عليه الجدارات المطلوبة ويحتاج إلى حل سريع
B13: الوصف | E13: نقاط الجدارات
B14: الجدارات الأساسية | E14: تعريف مستوى الجدارات (مؤشرات السلوك) | H14: النسبة | J14: النسبة "تحسب تلقائياً" | K14: ملاحظات حول البند
H15: م.ك | I15: الدرجة الفعلية
B16: التواصل و التعاون | E16: {=VLOOKUP(H16,'V-lookup'!B4:C8,2,FALSE)} -> يطلب مشاركة الأخرين يشاورهم و يبادر بالتواصل مع الأخرين يتناقش في وجهات نظر متعددة بوضوح و بطريقة بنائه يعرض و يوصل المعلومات و المعرفة لمجموعة من الناس يلتزم بوعوده للعميل يفهم أولويات الفريق و يكيف مهامة تبعاً لذلك ينمي أهداف الفريق أكثر من أهدافه يحافظ على السلوك الإيجابي لفريق العمل في الأوقات العصيبة يظهر الإلتزام للمنظمة و أهدافها و قيمها يفهم و يراعي متطلبات وظيفته | H16: 2 | I16: فعال | J16: {=IF(I16="مميز وكفء",105%,IF(I16="فعال",95%,IF(I16="جيد",85%,IF(I16="مقبول",70%,IF(I16="غير مرض",60%,IF(I16="ضعيف",0%,"#N/ A"))))))} -> 0.95
B17: المثابرة وتحقيق الانجازات | E17: {=VLOOKUP(H17,'V-lookup'!D4:E8,2,FALSE)} -> دائما يعمل علي انجاز مهامه وأهدافه بغض النظر عن الصعاب التي قد يواجهها يتحمل المسؤوليه تجاه عمله ونتائجه ويطلب التعليق عليه دائما يعمل علي تحسين نتائج عمله يسعى ويطلب التوجيه من المشرفين عند مواجهة الصعاب فى العمل يستكشف كل السبل الممكنة مع كل الأطراف فى العمل فى ضوء سلطاته | H17: 2 | I17: فعال | J17: {=IF(I17="مميز وكفء",105%,IF(I17="فعال",95%,IF(I17="جيد",85%,IF(I17="مقبول",70%,IF(I17="غير مرض",60%,IF(I17="ضعيف",0%,"#N/ A"))))))} -> 0.95
B18: الاهتمام بالعميل | E18: {=VLOOKUP(H18,'V-lookup'!F4:G8,2,FALSE)} -> يلتزم ويهتم بشؤون العميل. يحدد متطلبات العميل وتوقعاته. يوضح المزايا للعميل يتفهم العميل وموقفه يتقبل رد فعل العميل بطريقة ايجابية ويظهر الاستعداد لحل مشاكله. يلاحظ مشاكل وطلبات العميل ويستجيب لها فى اطار مسؤولياته | H18: 2 | I18: فعال | J18: {=IF(I18="مميز وكفء",105%,IF(I18="فعال",95%,IF(I18="جيد",85%,IF(I18="مقبول",70%,IF(I18="غير مرض",60%,IF(I18="ضعيف",0%,"#N/ A"))))))} -> 0.95
B20: الوصف | E20: نقاط الجدارات
A21: الكود | B21: الجدارات الفنية | E21: تعريف مستوى الجدارات (مؤشرات السلوك) | H21: النسبة | J21: النسبة "تحسب تلقائياً" | K21: ملاحظات حول البند
H22: أ.ف | I22: الدرجة الفعلية
A23: 1 | B23: {=VLOOKUP(A23,'V-lookup'!A12:C48,2,0)} -> التفكير التجاري | E23: {=VLOOKUP(H23,'V-lookup'!B14:C104,2,0)} -> يتفهم العلاقة بين وظفيته وتأثيره علي الشركة في السوق يستخدم معلوماته وخبرته لعمله كما يوجهه مشرفه يتقبل الأفكار الجديدة التي تفيد عمله. يحرص علي الاستخدام الامثل للموارد في العمل يتجنب اهدار الموارد في عمله يعرض بدائل متعددة للأخرين يبدأ علاقات مع العملاء والموردين طبقا لحاجة العمل | H23: 12 | I23: جيد | J23: {=IF(I23="مميز وكفء",105%,IF(I23="فعال",95%,IF(I23="جيد",85%,IF(I23="مقبول",70%,IF(I23="غير مرض",60%,IF(I23="ضعيف",0%,"#N/ A"))))))} -> 0.85
B27: الجدارات الاساسية | E27: الجدارات التخصية | F27: الجدارات القيادية
B28: 0.1 | E28: 0.1 | F28: 0
B29: التواصل والتعاون | C29: المثابرة وتحقيق الانجازات | D29: الاهتمام بالعميل
B30: {=J16} -> 0.95 | C30: {=J17} -> 0.95 | D30: {=J18} -> 0.95
B31: {=AVERAGE(B30:D30)} -> 0.95 | E31: 0.1 | F31: 0
B33: النسبة النهائية للجدارات: | E33: {=AVERAGE(B31,E31,F31)} -> 0.35
B36: ملاحظات (القائم بالتقييم)
B46: توقيع القائم بالتقييم | E46: توقيع الموظف | I46: اعتماد مدير الادارة
I98: مميز وكفء
I99: فعال
I100: جيد
I101: مقبول
I102: غير مرض
I103: ضعيف

Sheet Overall Performance Calculation
C4: نتيجة إجمالي الأداء
B5: المحور | C5: الجدارات | D5: الانتاجية وفقا للمؤشرات | E5: الالتزام الادارى يحسب بمعرفة الموارد البشرية | F5: إجمالي النسبة | G5: التقدير العام
B6: الدرجة العظمى | C6: 0.2 | D6: 0.7 | E6: 0.1
B7: النسبة الفعلية النهائية | C7: {='Non-Technical Competencies'!E33} -> 0.35 | D7: {='Objectives'!E16} -> 0.9 | F7: {=(C7*C6)+(D7*D6)+(E7*E6)} -> 0.7 | G7: {=IF(F7<60%,"ضعيف جدا ",IF(F7<70%,"غير مرض",IF(F7<80%,"مقبول",IF(F7<90%,"جيد",IF(F7<100%,"فعال",IF(F7>=100%,"متميز","Error"))))))} -> مقبول
C8: يتم النظر إلى كل محور على حدى فيجب ان يصاحب ارتفاع الانتاجية ايضا ارتفاع نسبة الجدارات وايضا نسبة الالتزام الادارى ( والعكس الصحيح )
C9: مواطن القوة عند الموظف | D9: ..........................................................................................................................................................................................................................................................................................
D10: ..........................................................................................................................................................................................................................................................................................
D11: ..........................................................................................................................................................................................................................................................................................
C12: مواطن الضعف التي تحتاج إلي تنمية | D12: ..........................................................................................................................................................................................................................................................................................
D13: ..........................................................................................................................................................................................................................................................................................
C14: الاقتراحات الفرص المتاحة لتحسين وتطوير الأداء (تملأ بمعرفة القائم بالتقييم )
C27: ملاحظات (القائم بالتقييم)
C41: الاقتراحات الفرص المتاحة لتحسين وتطوير الأداء (تملأ بمعرفة الموظف )
C55: ملاحظات (الموظف)
C67: توقيع القائم بالتقييم | E67: توقيع الموظف | F67: اعتماد مدير الادارة

Sheet Evidence
B1: التفسير و المررات (للحاصلين على "متميز" أو "ضعيف" )
B6: متميز * | D6: ضعيف جدا *
B61: توقيع القائم بالتقييم

Sheet V-lookup
B1: الجدارات الأساسية
B2: التواصل و التعاون | D2: المثابرة وتحقيق الانجازات | F2: الاهتمام بالعميل
B3: الإستماع للأخرين و التواصل الفعال معهم بطريقة تضمن التعاون مع أفراد فريق العمل للوصول إلى نتائج تفيد الصالح العام و الخاص. الاحساس بالانتماء والولاء للشركة والعمل في هذا الاطار | D3: دائما يعمل علي تحقيق أهدافه بغض النظر عن الصعاب التي قد يواجهها. لا تثبط العوائق من عزيمته. يحرص علي التغلب علي التحديات التي قد تؤثر علي انجاز الأهداف | F3: يسعي للتأكد من رضا العميل من خلال التفهم والوفاء بطلبات العميل مع القدرةعلي التكيف لتصميم الخدمات التي تقدمها الشركة بما يناسب العميل
B4: 1 | C4: يظهر الإهتمام بالأخرين و يستمع لهم بحيادية دون مقاطعة يتواصل بوضوح سواء كتابياً أو شفهياً ييلتزم باجراءات العمل وسئولياته يعرف دوره في فريق العمل و يعرف كيف يؤثر دوره على أهداف فريق العمل مستعد لإعطاء المساعدة للأخرين يعمل بطريقة تعاونية لا تنافسية يبدي النزاهة و الأداب المهنية الواضحة في العمل يلتزم و يتحمل مسؤلية مهماته | D4: 1 | E4: يعي دوره ومسئولياته تجاه نتائج عمله يقوم بتنفيذ الأعمال الموكلة اليه بالرغم من بعض العقبات البسيطة التي يمكن أن يواجهها يبدي رأيه فى الحوارات من أجل توضيح وجهة نظره | F4: 1 | G4: يفهم اهمية العميل بالنسبة للشركة وحتى وان لم يتعامل مع العميل بصورة مباشرة يستجيب بسرعة للاعمال الغير مباشرة المرسلة له والتى تتعلق بالعملاء يتعامل مع العميل باحترام فى حالة التعامل المباشر يستمع للعميل وينصت له باهتمام ويستجيب اليه بطريقة ودية يفهم متطلبات العميل
B5: 2 | C5: يطلب مشاركة الأخرين يشاورهم و يبادر بالتواصل مع الأخرين يتناقش في وجهات نظر متعددة بوضوح و بطريقة بنائه يعرض و يوصل المعلومات و المعرفة لمجموعة من الناس يلتزم بوعوده للعميل يفهم أولويات الفريق و يكيف مهامة تبعاً لذلك ينمي أهداف الفريق أكثر من أهدافه يحافظ على السلوك الإيجابي لفريق العمل في الأوقات العصيبة يظهر الإلتزام للمنظمة و أهدافها و قيمها يفهم و يراعي متطلبات وظيفته | D5: 2 | E5: دائما يعمل علي انجاز مهامه وأهدافه بغض النظر عن الصعاب التي قد يواجهها يتحمل المسؤوليه تجاه عمله ونتائجه ويطلب التعليق عليه دائما يعمل علي تحسين نتائج عمله يسعى ويطلب التوجيه من المشرفين عند مواجهة الصعاب فى العمل يستكشف كل السبل الممكنة مع كل الأطراف فى العمل فى ضوء سلطاته | F5: 2 | G5: يلتزم ويهتم بشؤون العميل. يحدد متطلبات العميل وتوقعاته. يوضح المزايا للعميل يتفهم العميل وموقفه يتقبل رد فعل العميل بطريقة ايجابية ويظهر الاستعداد لحل مشاكله. يلاحظ مشاكل وطلبات العميل ويستجيب لها فى اطار مسؤولياته
B6: 3 | C6: يأخذ أراء الأخرين في الإعتبار عندما يتواصل أو يتفاوض أو يعرض نقاط الإختلاف (مثلاً: يستطيع إستعراض مزايا من وجهات نظر مختلفة) يحافظ على التواصل الثنائي الإتجاه مع الناس المختلفة عندما يقوم بحل المشاكل المختلفة يتكيف في إسلوب تعامله بما يوائم الموقف يرد على و يناقش الإستفسارات و المواضيع بطريقة تشجع الأخرين على المشاركة من غير إتخاذ موقف دفاعي أو التعدي على كرامة الأخرين يقدم للاخرين يد العون لمساعدتهم في الالتزام بوعودهم يرعى روح الفريق و التعاون بداخل الفريق يستخدم مهارات تواصل شخصية فعالة يغير إسلوبه بنائاً على متطلبات أعضاء فريق العمل يتفهم مشاكل أعضاء الفريق و مدى تأثير هذه المشاكل عليهم لا يقبل العمل أو النتائج التي تنتهك قيم الشركة يوجه الأخرين و يساعدهم لإبقائهم ملتزمين لقيم و أهداف الشركة يظهر قيم الشركة في كل تعاملاته المهنية لديه قناعة و إحساس بالإنتماء للشركة | D6: 3 | E6: يبدى حس الملكية لأهداف الفريق ككل وليس أهدافه فقط. يقوم بتحقيق أهداف الفريق آخذا أهداف الادارة ككل فى الاعتبار يركز علي الأهداف ويبحث عن طرق وحلول بديلة للتغلب علي عقبات كبيرة فى العمل يتعامل بمرونة عند مواجهة المشاكل والعقبات فى العمل. يعمل بمستوى من الجهد والاتساق والمرونة فى المحادثات والتفاوضات الطويلة ولا يفقد الأمل فى اقناع الآخرين بما يفيد الشركة ويفيدهم | F6: 3 | G6: يبني ثقة و رابطة مع العميل يلتزم بالوعود للعميل يحدد طرق للحفاظ والبقاء علي العميل يبقي علي الاتصال المستمر مع العميل يتشارك المعلومات الخاصة بالعميل معه ويوفر له خيارات مختلفة لطلبه أو مشكلته يتشارك المعلومات بطريقة استباقية ويبادر بأفعال تناسب متطلباته
B7: 4 | C7: يقوم بتوصيل المعاومات الخاصة بمواضيع و قضايا معقدة بطريقة واضحة و بمصداقية مع مجموعات مختلفة من الناس يقوم بتقويم مشاكل التواصل يستخدم أليلت و مناهج تواصل مختلفة لتعزيز مفهوم الحوار و التفاهم المشترك لتقليص مشاكل التواصل يحث فريقه علي الالتزام بالوعود ويوجههم في ذلك يشجع الأخرين على مشاركة خبرتهم و معلوماتهم و أفضل طرق و أساليب العمل مع باقي الفريق يقوم بتنسيق و تيسير التفاهم في الفريق يستخدم المنطق و الحجة بطريقة مقنعة في تفسير قيمة الأفعال التي يقوم بها يستخدم و يبتكر أدوات و مناهج لرفع قيمة العمل الجماعي و تكامل الفريق لتحقيق الإنسجام و النوافق و المشاركة في الفريق ينصح الأخرين في الحفاظ على تعاملات مهنية عادلة و متناسقة مع الأخرين و خلال التعامل مع المعضلات الأخلاقية يمثل قدوة للأخرين في تمثيل قيم الشركة ينمي إحساس الولاء للشركة يضع أهداف الشركة و مصالحها قبل أهدافه و مصالحة | D7: 4 | E7: يلتزم بتحقيق أهدافه وأهداف الفريق من خلال نجاح الشركة ككل يتأكد أن الفريق دائما يعمل علي تحقيق أهدافه يوجه وينصح فريقه من أجل التركيز علي أهداف الادارة يكون مثل يحتذى به فى المثابرة من أجل التغلب علي مواقف التحدي والصعاب التي قد تواجه الفريق يبدأ اجتماعات المحادثات والمفاوضات ويتفاوض مع اطراف العمل ويعيد توجيه مسارات الحوار عند الابتعاد عنها يستطيع انهاء المفاوضات بما يفيد العمل مع اقتناع اطراف العمل الآخرين | F7: 4 | G7: يراقب ويعمل علي مقاييس لارضاء العميل ويتناول شكاوي العميل بجدية ينشئ وينمي قنوات الاتصال مع العملاء الأساسيين. يحدد طرق لاضافة قيمة للعميل. يحل المشاكل المتضاربة مع العميل بسبل مترابحة للجانبين يراقب رضا العملاء باستمرار من خلال الاتصال المستمر معه و يعالج مشاكله بسرعة. يحل مشاكل العملاء المصعدة له يقترح طرق مصمة خصيصا للعميل لتوفير خدمات الشركة التي توفي خدماته
B8: 5 | C8: يتواصل لتحقيق أهداف محددة (مثلا: يأخذ في عين الإعتبار جوانب مثل أفضل رسالة للعرض, و التوقيت و الإسلوب) يظهر قدرة على الخطابة العامة للمجموعات الكبيرة و المجموعات المكونة من مدراء و رؤساء قطاعات يطور و يرعى نظم تقدر التواصل الفعال الغير مقيد يكون مثال يحتذي به في الالتزام بالوعود امام الموظفين والعاملين الموردين يطور فرق قوية تستفيد من إختلافات في المهارات و الجدارات و الخبرات السابقة و ينشئ التعاون بينهم يقوم بتيسير التعاون عبر المنظمة و المنظمات المختلفة لتحقيق هدف مشترك يشارك في وضع قيم الشركة يرعى ثقافة شركة تقوي و تدعم الإحساس بالولاء و المسئولية يشجع المسئولية الشخصية و مسؤلية المنظمة تجاه قيم و أهداف الشركة | D8: 5 | E8: يعمل بالتنسيق مع باقي الادارات من أجل تحقيق أهداف الشركة ككل يتبني ثقافة المثابرة وتحقيق الانجازات يتعامل مع التحديات التي تواجهها الشركة بطريقة ايجابية لا يري هذه التحديات كفشل ولكن كتجربة وخبرة تتعلم منها الشركة يؤثر علي قرارات العميل أو اطراف العمل بما يفيد الشركة من خلال المفاوضات | F8: 5 | G8: ينمي نظم لتقييم وزيادة رضا العميل يبني خطط لعلاقات العملاء يدير العلاقات مع العملاء الممتازين الذين يؤثرون علي تحقيق اهداف الشركة و سمعتها في السوق يبني شبكات اتصال وعلاقات مفيدة للعمل يبني ويرعى الصورة العامة للشركة بالنسبة لعملائها الحاليين والمحتملين يعدل خطط العمل بما يناسب التغيرات فى متطلبات العملاء والسلوك فى السوق
B11: جدارات المجموعة التجارية
A12: 1 | B12: التفكير التجاري
B13: يتفهم طبيعة العمل في المجال الخاص بالشاركة ويفكر في افكار جديدة ويسعي الي فرص جديدة في العامل. يقبل التفاوض
B14: 11 | C14: يفهم السوق ومتطلباته في نطاق وظيفته يطلب العون من مشرفه في المواقف الجديدة يحمي الموارد التي يستخدمها اثناء عمله يتقبل مبدأ التفاوض
B15: 12 | C15: يتفهم العلاقة بين وظفيته وتأثيره علي الشركة في السوق يستخدم معلوماته وخبرته لعمله كما يوجهه مشرفه يتقبل الأفكار الجديدة التي تفيد عمله. يحرص علي الاستخدام الامثل للموارد في العمل يتجنب اهدار الموارد في عمله يعرض بدائل متعددة للأخرين يبدأ علاقات مع العملاء والموردين طبقا لحاجة العمل
B16: 13 | C16: يبدي الوعي بالفرص والعروض التي تقدمه الشركة يستخدم خبرته السابقة لخلق أفكار جديدة من أجل العمل يستخدم طرق اكثر فاعلية في استخدام الموارد للفريق يؤثر علي مجال الحوار وتغييره من أجل مصلحة العمل يتقبل أراء الأخرين ولا يصمم علي فكرته
B17: 14 | C17: يعرف الاشخاص والعلاقات الملوبة التي تفيد العمل يشجع الأخرين لبناء علاقات من أجل العمل يشارك خبرته ومعلوماته مع بقية اعضاء الفريق. يحدد الموارد المطلوبة والغير متوفر منها التي تؤثر علي الادارة يبدأ التفاوض ويغير من مساره من أجل العمل يهدف الي مسارات ترضي جميع الاطراف
B18: 15 | C18: يعرض افكار تنمي الشركة في مجالها يحدد خطط عمل الخاصة بالشركة طبقا لقوتها في السوق يعدل في خطط العمل طبقا للتغيرات في السوق يبدي الوعي بالفرص والمخاطر التي تؤثر علي الشركة يوجه الموارد للاستخدام الامثل في الادارة بم يفيد اهداف الشركة يقوم بانجاز مهام صفقات البيع ويناقشها بطريقة سهلة مقبولة للطرفين
A19: 2 | B19: الدقة والتنظيم
B20: يظهر الاهتمام بالتفاصيل اثناء عمله ويتأكد من درجة الدقة العالية في العمل. يقوم باعماله طبقا اللوائح والخطوات المحددة . يننظم مهامه ويضع اولويات لها لتحقيق الاهداف
B21: 21 | C21: يعي اهمية الدقة اثناء القيام بعمله يراجع عمله للتاكد من دقته يقوم بالاعمال الموكلة له بدقة يتتبع جدول الاعمال المطلوب منه يطلب المساعد من المشرفين أو الاكثر خبرة في حالة تعارض جداول العمل الموكلة له
B22: 22 | C22: يستطسع تحديد الاختلافات و الاخطاء المتكررة في العمل يقوم بتصحيح الاخطاء عند اكتشافها ينظم وقته من اجل تحقيق اهدافه تحت اشراف الاخرين يقوم بوضع اولويات عمله
B23: 23 | C23: يساعد الاخرين لتصحيح الاخطاء لا يقبل الأعمال التي بها أخطاء يراجع أعمال الاخرين وفريقة للتاكد من عدم وجود اخطاء يساعد الاخرين في الانتهاء من الاعمال في الوقت المحدد يساعد المشرفين فى وضع جداول العمل يقوم بعمل تغييرات في جدول اعماله عند تعارض المواعيد
B24: 24 | C24: يتأكد ويعمل علي تحسين مستوى الدقة للفريق وقدم لهم النصائح لذلك. يعي عواقب عدم الدقة في العمل والمخاطر التابعة لها يدير الموارد والوقت الخاص بالفريق للتاكد من ان العمل ساري بانتظام دون تعارض يقوم باعاددة تنظيم جداول العمل واعادة توزيع الموارد والاعمال عند الحاجة اثناء تعارض الجداول او حدوث تغير او نقص في الموارد.
B25: 25 | C25: يضع المعايير والقواعد العامة في الادارة الخاصة بالدقة والمتماشية مع المعايير الخاصة بالمجال يوجه الفريق للاهتمام والتركيز بالتفاصيل في العمل يبني جداول المشاريع المتكاملة ويقوم بتنظيم الاعمال والموارد للادارة للتاكد من عدم التعارض في الاعمال علي مستوي الادارة يحدد الطرق التي يمكن استخدام الموارد والوقت احسان استخدام لتحقيق الاهداف
A26: 3 | B26: تطبيق الخبرة والمعرفة في مجال العمل
B27: يستخدم خبرته ومعرفتف السابقة من أجل حل المشااكل وانجاز الاعمال
B28: 31 | C28: يتقبل المعلومات الجديدة يحل المساكل المتكررة المعروفة الخاصة بعمله يطلب العون من المشرفين لحل المشاكل الغير مألوفة
B29: 32 | C29: يسعي للخصول علي معلومات جديدة خاصة بعمله يفكر بحلول للمشاكل الموكلة اليه من المشرفين يطلب النصح من المشرفين لاخذ قرارات لحل مشاكل محددة موكلة غير قابل علي حلها يبدي المثابرة لحل المشاكل عن طريق البحث عن حلول متعدد
B30: 33 | C30: يطبق المعلومات والخبرة الخاصة به في مجاله في العمل يتأكد دائما من ان الفريق يعلم المعلومات الجديدة الخاصة بمجال العمل يساعد الفريق عن طريق خبرته في المجال يفكر في بدائل لحل مشاكل متعددة يقترح حلول لمشاكل معقدة علي اساس حساب المخاطر الخاصة بها
B31: 34 | C31: دائما يقيم مستوة امعرفة في الفريق ويحدد الجوانب التي تحتاج تنمية يفكر في حلول غير تقليدية لمشاكل معقدة يستطيع ان يحل المشاكل الغير مالوفة التي تؤثر علي العمل
B32: 35
A33: 4 | B33: الابتكار
B34: يتقبل الافكار والحلول الجديدة ويفكر بطريقة ابتكارية
B35: 41 | C35: يتقبل الافكار الجديد
B36: 41 | C36: يفكر خارج النطاق المعتاد ويرى المواقف من منظور مختلف يخلق افكار جديدة يقترح طرق جديدة لعمل الفريق
B37: 43 | C37: يسعي الي طرق جديدة مبتكرة في العمل ويشارك الاخرين بها يسعي الي معرفة كل جديد في مجال عمله يقترح وينفذ حلول جديدة مبتكرة يحول الافكار الي حلول فعالة
B38: 44 | C38: يشجع الاخرين للابتكار في العمل يسعي الي الحصول علي افكار جديدة من خارج الفريق يقترح افكار وحلول علي مستوى اعل من نطاق عمله يفكر في حلول مستقبلية سوف تفيد العمل
B39: 45 | C39: يشجغ الابتكار في الادارة ويحفز الفريق علي ذلك يفكر في افكار وحلول لتحسين العمل يشجع الفريق علي عرض افكار جديدة
C41: الجدارات القيادية
A42: 5 | B42: التاثير علي الآخرين وتنمية الفريق
B43: 51 | C43: يتفهم الشركة ورؤيتها جيدا.له تأثير عل الفريق لتحقيق اهدافه ولاستمرار الالتزام تجاه رؤية وخطط الشركة.يبني فرق متناغمة تستطيع التواصل والعمل من أجل رفع أداء الشركة.ينمي فرق ليسطيعوا اتخاذ القرارات ليقودوا الشركة في المستقبل
...
