Workbook

Sheet لوحة_التحكم
A1: لوحة التحكم التنفيذية – تقرير ضمان الجودة الفني
A2: نموذج تشغيلي تراكمي لمجمع سكني يضم 120 فيلا – جميع المؤشرات مرتبطة بالشيتات التشغيلية
A4: المؤشرات التنفيذية الرئيسية | H4: توزيع الفيلات حسب المرحلة | K4: أبرز ملاحظات الإدارة
A5: المؤشر | B5: القيمة | C5: المستهدف | D5: الحالة | E5: تعليق | H5: المرحلة | I5: العدد | K5: أولوية 1 | L5: خفض هدر اللياسة والدهانات وربطه بالاستلام الموقعي
A6: إجمالي عدد الفيلات | B6: {=120} -> 120 | C6: 120 | D6: {=IF(B6=C6,"ضمن الهدف","محدث")} -> ضمن الهدف | E6: حجم المشروع | H6: حفر | I6: 20 | K6: أولوية 2 | L6: رفع القبول من أول مرة في التشطيبات النهائية
A7: متوسط الإنجاز الكلي | B7: 0.55787167 | C7: 0.58 | D7: {=IF(B7>=C7,"ضمن الهدف",IF(B7>=C7*0.95,"قريب من الهدف","بحاجة إلى تحسين"))} -> قريب من الهدف | E7: التراكم حتى تاريخ التقرير | H7: أساسات | I7: 18 | K7: أولوية 3 | L7: إغلاق العيوب الحرجة قبل دفعة التسليم التالية
A8: مؤشر الجودة العام | B8: 0.96496547 | C8: 0.9 | D8: {=IF(B8>=C8,"ضمن الهدف",IF(B8>=C8*0.95,"قريب من الهدف","بحاجة إلى تحسين"))} -> ضمن الهدف | E8: ناتج الأوزان المحققة | H8: هيكل | I8: 22 | K8: أولوية 4 | L8: الاستمرار في تحديث سجل المخاطر وربطه بالقرار التنفيذي
A9: نسبة القبول من أول مرة | B9: 0.86857143 | C9: 0.9 | D9: {=IF(B9>=C9,"ضمن الهدف",IF(B9>=C9*0.95,"قريب من الهدف","بحاجة إلى تحسين"))} -> قريب من الهدف | E9: جودة التنفيذ قبل إعادة الفحص | H9: كهروميكانيك | I9: 16
A10: نسبة إغلاق العيوب | B10: 0.7443609 | C10: 0.9 | D10: {=IF(B10>=C10,"ضمن الهدف",IF(B10>=C10*0.95,"قريب من الهدف","بحاجة إلى تحسين"))} -> بحاجة إلى تحسين | E10: سرعة الإغلاق مقارنة بإجمالي العيوب | H10: تشطيبات | I10: 20
A11: نسبة الهدر المباشر | B11: 0.014023837 | C11: 0.05 | D11: {=IF(B11<=C11,"ضمن الهدف",IF(B11<=C11*1.15,"قريب من الهدف","بحاجة إلى تحسين"))} -> ضمن الهدف | E11: كلما انخفضت كانت الكفاءة أعلى | H11: مكتملة | I11: 24
A12: العيوب المفتوحة | B12: 102 | C12: 85 | D12: {=IF(B12<=C12,"ضمن الهدف",IF(B12<=C12*1.15,"قريب من الهدف","بحاجة إلى تحسين"))} -> بحاجة إلى تحسين | E12: حجم الملاحظات غير المغلقة
A13: الفيلات الجاهزة للتسليم | B13: 24 | C13: 18 | D13: {=IF(B13>=C13,"ضمن الهدف",IF(B13>=C13*0.95,"قريب من الهدف","بحاجة إلى تحسين"))} -> ضمن الهدف | E13: جاهزة للاستلام الابتدائي | H13: ملخص أداء المقاولين
H14: المقاول | I14: التقييم النهائي
H15: شركة البنيان المتقدم | I15: 80.9
H16: شركة الأنظمة المتكاملة | I16: 78.6
H17: شركة الإتقان للتشطيبات | I17: 77.4
H18: شركة العزل والبنية الحديثة | I18: 77.7

Sheet المدخلات
A1: مدخلات المشروع والمقاييس المرجعية
A2: يضم معلومات المشروع الأساسية، القيم المرجعية، والمؤشرات المحسوبة التي تغذي لوحة التحكم وهيكل الجودة
A4: بيانات المشروع الأساسية
A5: اسم المشروع | B5: مشروع عينة لمجمع سكني – 120 فيلا | C5: تاريخ بدء المشروع | D5: 45662
A6: تاريخ التقرير | B6: 46112 | C6: مدة المشروع المخططة | D6: 24 شهر
A7: عدد الفيلات | B7: 120 | C7: عدد القطاعات | D7: 4
A8: الميزانية الكلية | B8: 278000000 | C8: قيمة الأعمال المنفذة حتى التقرير | D8: 154800000
A9: متوسط الإنجاز التراكمي المستهدف حتى التقرير | B9: 0.58 | C9: متوسط الإنجاز الفعلي
A11: مقاييس مرجعية إدارية | D11: مؤشرات محسوبة من البيانات التشغيلية
A12: المؤشر المرجعي | B12: القيمة | D12: المؤشر المحسوب | E12: القيمة | F12: المستهدف | G12: ملاحظة
A13: اكتمال خطة الجودة | B13: 0.96 | D13: متوسط الإنجاز الكلي | E13: 0.55787167 | F13: 0.58 | G13: مرجعه سجل الفيلات
A14: انتظام اجتماعات الجودة | B14: 0.91 | D14: نسبة القبول من أول مرة | E14: {=COUNTIF('الفحوصات_والاختبارات'!$G$5:$G$704,"مقبول من أول مرة")/COUNTA('الفحوصات_والاختبارات'!$A$5:$A$704)} -> 0.86857143 | F14: 0.9 | G14: مرجعها سجل الفحوصات
A15: وضوح الأدوار والمسؤوليات | B15: 0.93 | D15: نسبة الفحوصات غير المرفوضة | E15: {=1-(COUNTIF('الفحوصات_والاختبارات'!$G$5:$G$704,"مرفوض")/COUNTA('الفحوصات_والاختبارات'!$A$5:$A$704))} -> 0.99142857 | F15: 0.98 | G15: تتضمن المقبول بعد إعادة
A16: تحديث سجل المخاطر | B16: 0.88 | D16: نسبة إغلاق العيوب | E16: 0.7443609 | F16: 0.9 | G16: مرجعها سجل العيوب
A17: اكتمال مراجعات التصميم | B17: 0.95 | D17: عدد العيوب المفتوحة | E17: 102 | F17: 85 | G17: الهدف خفضها تدريجيًا
A18: اعتماد الموردين والمواد | B18: 0.94 | D18: متوسط مدة إغلاق العيوب | E18: 12.070707 | F18: 14 | G18: بالأيام
A19: معدل مطابقة المواد الواردة | B19: 0.95 | D19: تكلفة إعادة العمل التراكمية | E19: 1070381 | F19: 0 | G19: من سجل العيوب
A20: نظافة الموقع وإدارة المخلفات | B20: 0.87 | D20: نسبة الهدر المباشر | E20: 0.014023837 | F20: 0.05 | G20: من شيت هدر الموارد
A21: الالتزام بضبط الوثائق والسجلات | B21: 0.93 | D21: عدد الفيلات الجاهزة للتسليم | E21: 24 | F21: 18 | G21: من شيت الاستلام
A22: التكامل بين الجودة والسلامة | B22: 0.9 | D22: متوسط تقييم المقاولين | E22: 78.65 | F22: 85 | G22: من شيت أداء المقاولين
A23: رضا العميل بعد التسليم | B23: 0.89
A24: الالتزام بإصدار التقارير الدورية | B24: 0.92
A25: إغلاق الإجراءات التصحيحية والوقائية | B25: 0.88

Sheet هيكل_الجودة
A1: هيكل ضمان الجودة المتكامل – البنود الرئيسية الستة عشر
A2: الجزء العلوي للتقييم الموزون، والجزء السفلي للتفصيل الفرعي وآليات المتابعة
A4: التقييم الرئيسي الموزون
A5: رقم | B5: البند الرئيسي | C5: الوزن النسبي | D5: نوع القياس | E5: المؤشر الحالي | F5: المستهدف | G5: درجة التقييم | H5: الوزن المحقق
A6: 1 | B6: الحوكمة ونظام إدارة الجودة | C6: 0.06 | D6: أعلى أفضل | E6: 0.93333333 | F6: 0.95 | G6: {=IF(D6="أعلى أفضل",MIN(E6/F6,1),MIN(F6/E6,1))} -> 0.98245614 | H6: {=C6*G6} -> 0.058947368
A7: 2 | B7: إدارة المخاطر المرتبطة بالجودة | C7: 0.05 | D7: أعلى أفضل | E7: 0.88 | F7: 0.9 | G7: {=IF(D7="أعلى أفضل",MIN(E7/F7,1),MIN(F7/E7,1))} -> 0.97777778 | H7: {=C7*G7} -> 0.048888889
A8: 3 | B8: ضبط جودة الدراسات والتصميمات | C8: 0.07 | D8: أعلى أفضل | E8: 0.95 | F8: 0.95 | G8: {=IF(D8="أعلى أفضل",MIN(E8/F8,1),MIN(F8/E8,1))} -> 1 | H8: {=C8*G8} -> 0.07
A9: 4 | B9: إدارة التعاقدات والموردين من منظور الجودة | C9: 0.05 | D9: أعلى أفضل | E9: 0.94 | F9: 0.95 | G9: {=IF(D9="أعلى أفضل",MIN(E9/F9,1),MIN(F9/E9,1))} -> 0.98947368 | H9: {=C9*G9} -> 0.049473684
A10: 5 | B10: جودة المواد والمنتجات | C10: 0.07 | D10: أعلى أفضل | E10: 0.95 | F10: 0.95 | G10: {=IF(D10="أعلى أفضل",MIN(E10/F10,1),MIN(F10/E10,1))} -> 1 | H10: {=C10*G10} -> 0.07
A11: 6 | B11: جودة التنفيذ في الموقع | C11: 0.13 | D11: أعلى أفضل | E11: 0.86857143 | F11: 0.9 | G11: {=IF(D11="أعلى أفضل",MIN(E11/F11,1),MIN(F11/E11,1))} -> 0.96507937 | H11: {=C11*G11} -> 0.12546032
A12: 7 | B12: التفتيش والاختبارات الفنية | C12: 0.08 | D12: أعلى أفضل | E12: 0.99142857 | F12: 0.98 | G12: {=IF(D12="أعلى أفضل",MIN(E12/F12,1),MIN(F12/E12,1))} -> 1 | H12: {=C12*G12} -> 0.08
A13: 8 | B13: إدارة المخلفات والنظافة في الموقع | C13: 0.05 | D13: أعلى أفضل | E13: 0.87 | F13: 0.9 | G13: {=IF(D13="أعلى أفضل",MIN(E13/F13,1),MIN(F13/E13,1))} -> 0.96666667 | H13: {=C13*G13} -> 0.048333333
A14: 9 | B14: إدارة العيوب وعدم المطابقة | C14: 0.08 | D14: أعلى أفضل | E14: 0.7443609 | F14: 0.9 | G14: {=IF(D14="أعلى أفضل",MIN(E14/F14,1),MIN(F14/E14,1))} -> 0.82706767 | H14: {=C14*G14} -> 0.066165414
A15: 10 | B15: ضبط الوثائق والسجلات | C15: 0.05 | D15: أعلى أفضل | E15: 0.93 | F15: 0.95 | G15: {=IF(D15="أعلى أفضل",MIN(E15/F15,1),MIN(F15/E15,1))} -> 0.97894737 | H15: {=C15*G15} -> 0.048947368
A16: 11 | B16: إدارة الجودة للمقاولين الفرعيين | C16: 0.06 | D16: أعلى أفضل | E16: 0.7865 | F16: 0.85 | G16: {=IF(D16="أعلى أفضل",MIN(E16/F16,1),MIN(F16/E16,1))} -> 0.92529412 | H16: {=C16*G16} -> 0.055517647
A17: 12 | B17: التكامل بين الجودة والسلامة | C17: 0.04 | D17: أعلى أفضل | E17: 0.9 | F17: 0.92 | G17: {=IF(D17="أعلى أفضل",MIN(E17/F17,1),MIN(F17/E17,1))} -> 0.97826087 | H17: {=C17*G17} -> 0.039130435
... A21: 16 | B21: إدارة هدر الموارد وكفاءة الاستخدام | C21: 0.07 | D21: أقل أفضل | E21: 0.014023837 | F21: 0.05 | G21: {=IF(D21="أعلى أفضل",MIN(E21/F21,1),MIN(F21/E21,1))} -> 1 | H21: {=C21*G21} -> 0.07
A23: التفصيل الفرعي للبنود الرئيسية
A24: رقم البند | B24: البند الرئيسي | C24: البند الفرعي | D24: آلية المتابعة أو جهة التحقق
A25: 1 | B25: الحوكمة ونظام إدارة الجودة | C25: وجود سياسة جودة معتمدة ومعلنة | D25: الإدارة الداخلية للمشروع
A26: 1 | B26: الحوكمة ونظام إدارة الجودة | C26: تحديد المسؤوليات ونطاق الصلاحيات | D26: مدير المشروع وضابط الجودة
A27: 1 | B27: الحوكمة ونظام إدارة الجودة | C27: اعتماد خطة الجودة وربطها بالجدول | D27: فريق التخطيط والجودة
A28: 1 | B28: الحوكمة ونظام إدارة الجودة | C28: مراجعة دورية لمؤشرات الجودة | D28: اجتماع الإدارة الأسبوعي
A29: 2 | B29: إدارة المخاطر المرتبطة بالجودة | C29: حصر المخاطر الفنية والتشغيلية | D29: سجل المخاطر
A30: 2 | B30: إدارة المخاطر المرتبطة بالجودة | C30: تقييم الاحتمال والأثر | D30: لجنة المخاطر
A31: 2 | B31: إدارة المخاطر المرتبطة بالجودة | C31: تحديث المعالجات الوقائية | D31: المتابعة الأسبوعية
A32: 2 | B32: إدارة المخاطر المرتبطة بالجودة | C32: ربط المخاطر بنقاط الفحص الحرجة | D32: خطة الفحص والاختبار
A33: 3 | B33: ضبط جودة الدراسات والتصميمات | C33: مراجعة التربة والموقع والخدمات | D33: الاستشاري المصمم
A34: 3 | B34: ضبط جودة الدراسات والتصميمات | C34: كشف التعارضات بين التخصصات | D34: اجتماعات التنسيق
A35: 3 | B35: ضبط جودة الدراسات والتصميمات | C35: اعتماد الرسومات التنفيذية | D35: سجل الاعتمادات
A36: 3 | B36: ضبط جودة الدراسات والتصميمات | C36: التأكد من الالتزام بالأكواد | D36: المراجعة الفنية
... A88: 16 | B88: إدارة هدر الموارد وكفاءة الاستخدام | C88: اتخاذ إجراءات لتقليل إعادة العمل | D88: الإدارة الفنية

Sheet متابعة_الفيلات
A1: متابعة حالة الفيلات والتقدم الفني
A2: السجل التشغيلي الرئيس للوحدات، ويرتبط تلقائيًا بالفحوصات والعيوب والتسليم
A4: رقم الفيلا | B4: القطاع | C4: الطراز | D4: المرحلة الحالية | E4: نسبة الإنجاز | F4: المقاول الرئيسي | G4: إجمالي الفحوصات | H4: قبول من أول مرة | I4: نسبة القبول | J4: العيوب المفتوحة | K4: العيوب المغلقة | L4: تكلفة إعادة العمل | M4: حالة الجودة | N4: تاريخ التسليم المخطط | O4: تاريخ التسليم المتوقع | P4: انحراف الأيام | Q4: حالة الوحدة
A5: 1 | B5: القطاع أ | C5: نموذج أ | D5: حفر | E5: 0.1189 | F5: شركة البنيان المتقدم | G5: {=COUNTIF('الفحوصات_والاختبارات'!$C$5:$C$704,A5)} -> 1 | H5: {=_xlfn.COUNTIFS('الفحوصات_والاختبارات'!$C$5:$C$704,A5,'الفحوصات_والاختبارات'!$G$5:$G$704,"مقبول من أول مرة")} -> 1 | I5: {=_xlfn.IFERROR(H5/G5,0)} -> 1 | J5: 0 | K5: 0 | L5: 0 | M5: {=IF(AND(I5>=0.9,J5<=2),"مستقرة",IF(AND(I5>=0.82,J5<=5),"تحت المراقبة","حرجة"))} -> مستقرة | N5: 46052 | O5: 46135 | P5: {=O5-N5} -> 83 | Q5: {=IF(D5="مكتملة","مرشحة للتسليم",IF(D5="تشطيبات","قيد التجهيز","تحت التنفيذ"))} -> تحت التنفيذ
A6: 2 | B6: القطاع أ | C6: نموذج ب | D6: حفر | E6: 0.1423 | F6: شركة البنيان المتقدم | G6: {=COUNTIF('الفحوصات_والاختبارات'!$C$5:$C$704,A6)} -> 1 | H6: {=_xlfn.COUNTIFS('الفحوصات_والاختبارات'!$C$5:$C$704,A6,'الفحوصات_والاختبارات'!$G$5:$G$704,"مقبول من أول مرة")} -> 1 | I6: {=_xlfn.IFERROR(H6/G6,0)} -> 1 | J6: 0 | K6: 2 | L6: 1469 | M6: {=IF(AND(I6>=0.9,J6<=2),"مستقرة",IF(AND(I6>=0.82,J6<=5),"تحت المراقبة","حرجة"))} -> مستقرة | N6: 46055 | O6: 46148 | P6: {=O6-N6} -> 93 | Q6: {=IF(D6="مكتملة","مرشحة للتسليم",IF(D6="تشطيبات","قيد التجهيز","تحت التنفيذ"))} -> تحت التنفيذ
A7: 3 | B7: القطاع أ | C7: نموذج ج | D7: حفر | E7: 0.1353 | F7: شركة البنيان المتقدم | G7: {=COUNTIF('الفحوصات_والاختبارات'!$C$5:$C$704,A7)} -> 1 | H7: {=_xlfn.COUNTIFS('الفحوصات_والاختبارات'!$C$5:$C$704,A7,'الفحوصات_والاختبارات'!$G$5:$G$704,"مقبول من أول مرة")} -> 1 | I7: {=_xlfn.IFERROR(H7/G7,0)} -> 1 | J7: 1 | K7: 0 | L7: 942 | M7: {=IF(AND(I7>=0.9,J7<=2),"مستقرة",IF(AND(I7>=0.82,J7<=5),"تحت المراقبة","حرجة"))} -> مستقرة | N7: 46058 | O7: 46165 | P7: {=O7-N7} -> 107 | Q7: {=IF(D7="مكتملة","مرشحة للتسليم",IF(D7="تشطيبات","قيد التجهيز","تحت التنفيذ"))} -> تحت التنفيذ
A8: 4 | B8: القطاع أ | C8: نموذج أ | D8: حفر | E8: 0.1419 | F8: شركة البنيان المتقدم | G8: {=COUNTIF('الفحوصات_والاختبارات'!$C$5:$C$704,A8)} -> 1 | H8: {=_xlfn.COUNTIFS('الفحوصات_والاختبارات'!$C$5:$C$704,A8,'الفحوصات_والاختبارات'!$G$5:$G$704,"مقبول من أول مرة")} -> 1 | I8: {=_xlfn.IFERROR(H8/G8,0)} -> 1 | J8: 1 | K8: 1 | L8: 5138 | M8: {=IF(AND(I8>=0.9,J8<=2),"مستقرة",IF(AND(I8>=0.82,J8<=5),"تحت المراقبة","حرجة"))} -> مستقرة | N8: 46061 | O8: 46147 | P8: {=O8-N8} -> 86 | Q8: {=IF(D8="مكتملة","مرشحة للتسليم",IF(D8="تشطيبات","قيد التجهيز","تحت التنفيذ"))} -> تحت التنفيذ
A9: 5 | B9: القطاع أ | C9: نموذج ب | D9: حفر | E9: 0.1199 | F9: شركة البنيان المتقدم | G9: {=COUNTIF('الفحوصات_والاختبارات'!$C$5:$C$704,A9)} -> 1 | H9: {=_xlfn.COUNTIFS('الفحوصات_والاختبارات'!$C$5:$C$704,A9,'الفحوصات_والاختبارات'!$G$5:$G$704,"مقبول من أول مرة")} -> 1 | I9: {=_xlfn.IFERROR(H9/G9,0)} -> 1 | J9: 1 | K9: 1 | L9: 3214 | M9: {=IF(AND(I9>=0.9,J9<=2),"مستقرة",IF(AND(I9>=0.82,J9<=5),"تحت المراقبة","حرجة"))} -> مستقرة | N9: 46064 | O9: 46156 | P9: {=O9-N9} -> 92 | Q9: {=IF(D9="مكتملة","مرشحة للتسليم",IF(D9="تشطيبات","قيد التجهيز","تحت التنفيذ"))} -> تحت التنفيذ
A10: 6 | B10: القطاع أ | C10: نموذج ج | D10: حفر | E10: 0.1271 | F10: شركة البنيان المتقدم | G10: {=COUNTIF('الفحوصات_والاختبارات'!$C$5:$C$704,A10)} -> 1 | H10: {=_xlfn.COUNTIFS('الفحوصات_والاختبارات'!$C$5:$C$704,A10,'الفحوصات_والاختبارات'!$G$5:$G$704,"مقبول من أول مرة")} -> 1 | I10: {=_xlfn.IFERROR(H10/G10,0)} -> 1 | J10: 0 | K10: 2 | L10: 5556 | M10: {=IF(AND(I10>=0.9,J10<=2),"مستقرة",IF(AND(I10>=0.82,J10<=5),"تحت المراقبة","حرجة"))} -> مستقرة | N10: 46067 | O10: 46145 | P10: {=O10-N10} -> 78 | Q10: {=IF(D10="مكتملة","مرشحة للتسليم",IF(D10="تشطيبات","قيد التجهيز","تحت التنفيذ"))} -> تحت التنفيذ
A11: 7 | B11: القطاع أ | C11: نموذج أ | D11: حفر | E11: 0.1333 | F11: شركة البنيان المتقدم | G11: {=COUNTIF('الفحوصات_والاختبارات'!$C$5:$C$704,A11)} -> 1 | H11: {=_xlfn.COUNTIFS('الفحوصات_والاختبارات'!$C$5:$C$704,A11,'الفحوصات_والاختبارات'!$G$5:$G$704,"مقبول من أول مرة")} -> 1 | I11: {=_xlfn.IFERROR(H11/G11,0)} -> 1 | J11: 0 | K11: 2 | L11: 9782 | M11: {=IF(AND(I11>=0.9,J11<=2),"مستقرة",IF(AND(I11>=0.82,J11<=5),"تحت المراقبة","حرجة"))} -> مستقرة | N11: 46070 | O11: 46155 | P11: {=O11-N11} -> 85 | Q11: {=IF(D11="مكتملة","مرشحة للتسليم",IF(D11="تشطيبات","قيد التجهيز","تحت التنفيذ"))} -> تحت التنفيذ
A12: 8 | B12: القطاع أ | C12: نموذج ب | D12: حفر | E12: 0.1079 | F12: شركة البنيان المتقدم | G12: {=COUNTIF('الفحوصات_والاختبارات'!$C$5:$C$704,A12)} -> 1 | H12: {=_xlfn.COUNTIFS('الفحوصات_والاختبارات'!$C$5:$C$704,A12,'الفحوصات_والاختبارات'!$G$5:$G$704,"مقبول من أول مرة")} -> 1 | I12: {=_xlfn.IFERROR(H12/G12,0)} -> 1 | J12: 2 | K12: 0 | L12: 10864 | M12: {=IF(AND(I12>=0.9,J12<=2),"مستقرة",IF(AND(I12>=0.82,J12<=5),"تحت المراقبة","حرجة"))} -> مستقرة | N12: 46073 | O12: 46191 | P12: {=O12-N12} -> 118 | Q12: {=IF(D12="مكتملة","مرشحة للتسليم",IF(D12="تشطيبات","قيد التجهيز","تحت التنفيذ"))} -> تحت التنفيذ
A13: 9 | B13: القطاع أ | C13: نموذج ج | D13: حفر | E13: 0.141 | F13: شركة البنيان المتقدم | G13: {=COUNTIF('الفحوصات_والاختبارات'!$C$5:$C$704,A13)} -> 1 | H13: {=_xlfn.COUNTIFS('الفحوصات_والاختبارات'!$C$5:$C$704,A13,'الفحوصات_والاختبارات'!$G$5:$G$704,"مقبول من أول مرة")} -> 1 | I13: {=_xlfn.IFERROR(H13/G13,0)} -> 1 | J13: 1 | K13: 1 | L13: 1597 | M13: {=IF(AND(I13>=0.9,J13<=2),"مستقرة",IF(AND(I13>=0.82,J13<=5),"تحت المراقبة","حرجة"))} -> مستقرة | N13: 46076 | O13: 46187 | P13: {=O13-N13} -> 111 | Q13: {=IF(D13="مكتملة","مرشحة للتسليم",IF(D13="تشطيبات","قيد التجهيز","تحت التنفيذ"))} -> تحت التنفيذ
A14: 10 | B14: القطاع أ | C14: نموذج أ | D14: حفر | E14: 0.1072 | F14: شركة البنيان المتقدم | G14: {=COUNTIF('الفحوصات_والاختبارات'!$C$5:$C$704,A14)} -> 1 | H14: {=_xlfn.COUNTIFS('الفحوصات_والاختبارات'!$C$5:$C$704,A14,'الفحوصات_والاختبارات'!$G$5:$G$704,"مقبول من أول مرة")} -> 1 | I14: {=_xlfn.IFERROR(H14/G14,0)} -> 1 | J14: 0 | K14: 2 | L14: 1497 | M14: {=IF(AND(I14>=0.9,J14<=2),"مستقرة",IF(AND(I14>=0.82,J14<=5),"تحت المراقبة","حرجة"))} -> مستقرة | N14: 46079 | O14: 46196 | P14: {=O14-N14} -> 117 | Q14: {=IF(D14="مكتملة","مرشحة للتسليم",IF(D14="تشطيبات","قيد التجهيز","تحت التنفيذ"))} -> تحت التنفيذ
A15: 11 | B15: القطاع أ | C15: نموذج ب | D15: حفر | E15: 0.0915 | F15: شركة البنيان المتقدم | G15: {=COUNTIF('الفحوصات_والاختبارات'!$C$5:$C$704,A15)} -> 1 | H15: {=_xlfn.COUNTIFS('الفحوصات_والاختبارات'!$C$5:$C$704,A15,'الفحوصات_والاختبارات'!$G$5:$G$704,"مقبول من أول مرة")} -> 1 | I15: {=_xlfn.IFERROR(H15/G15,0)} -> 1 | J15: 0 | K15: 2 | L15: 1315 | M15: {=IF(AND(I15>=0.9,J15<=2),"مستقرة",IF(AND(I15>=0.82,J15<=5),"تحت المراقبة","حرجة"))} -> مستقرة | N15: 46082 | O15: 46177 | P15: {=O15-N15} -> 95 | Q15: {=IF(D15="مكتملة","مرشحة للتسليم",IF(D15="تشطيبات","قيد التجهيز","تحت التنفيذ"))} -> تحت التنفيذ
A16: 12 | B16: القطاع أ | C16: نموذج ج | D16: حفر | E16: 0.1488 | F16: شركة البنيان المتقدم | G16: {=COUNTIF('الفحوصات_والاختبارات'!$C$5:$C$704,A16)} -> 1 | H16: {=_xlfn.COUNTIFS('الفحوصات_والاختبارات'!$C$5:$C$704,A16,'الفحوصات_والاختبارات'!$G$5:$G$704,"مقبول من أول مرة")} -> 1 | I16: {=_xlfn.IFERROR(H16/G16,0)} -> 1 | J16: 0 | K16: 0 | L16: 0 | M16: {=IF(AND(I16>=0.9,J16<=2),"مستقرة",IF(AND(I16>=0.82,J16<=5),"تحت المراقبة","حرجة"))} -> مستقرة | N16: 46085 | O16: 46196 | P16: {=O16-N16} -> 111 | Q16: {=IF(D16="مكتملة","مرشحة للتسليم",IF(D16="تشطيبات","قيد التجهيز","تحت التنفيذ"))} -> تحت التنفيذ
... A124: 120 | B124: القطاع د | C124: نموذج ج | D124: مكتملة | E124: 0.9739 | F124: شركة الإتقان للتشطيبات | G124: {=COUNTIF('الفحوصات_والاختبارات'!$C$5:$C$704,A124)} -> 10 | H124: {=_xlfn.COUNTIFS('الفحوصات_والاختبارات'!$C$5:$C$704,A124,'الفحوصات_والاختبارات'!$G$5:$G$704,"مقبول من أول مرة")} -> 8 | I124: {=_xlfn.IFERROR(H124/G124,0)} -> 0.8 | J124: 0 | K124: 6 | L124: 5232 | M124: {=IF(AND(I124>=0.9,J124<=2),"مستقرة",IF(AND(I124>=0.82,J124<=5),"تحت المراقبة","حرجة"))} -> حرجة | N124: 46469 | O124: 46467 | P124: {=O124-N124} -> -2 | Q124: {=IF(D124="مكتملة","مرشحة للتسليم",IF(D124="تشطيبات","قيد التجهيز","تحت التنفيذ"))} -> مرشحة للتسليم

Sheet الفحوصات_والاختبارات
A1: سجل الفحوصات والاختبارات الفنية
A2: بيانات تراكمية حتى 2026-03-31 لعدد 120 فيلا ضمن مشروع المجمع السكني
A4: رقم الفحص | B4: تاريخ الفحص | C4: رقم الفيلا | D4: القطاع | E4: البند المفحوص | F4: الجهة المنفذة | G4: نتيجة الفحص | H4: عدد مرات الإعادة | I4: ملاحظات
A5: فحص-0001 | B5: 45663 | C5: 1 | D5: القطاع أ | E5: أعمال الحفر والتسوية | F5: شركة البنيان المتقدم | G5: مقبول من أول مرة | H5: 0 | I5: تم الفحص وفق الخطة واعتماد العمل دون ملاحظات جوهرية
A6: فحص-0002 | B6: 45667 | C6: 2 | D6: القطاع أ | E6: أعمال الحفر والتسوية | F6: شركة البنيان المتقدم | G6: مقبول من أول مرة | H6: 0 | I6: تم الفحص وفق الخطة واعتماد العمل دون ملاحظات جوهرية
A7: فحص-0003 | B7: 45671 | C7: 3 | D7: القطاع أ | E7: أعمال الحفر والتسوية | F7: شركة البنيان المتقدم | G7: مقبول من أول مرة | H7: 0 | I7: تم الفحص وفق الخطة واعتماد العمل دون ملاحظات جوهرية
A8: فحص-0004 | B8: 45668 | C8: 4 | D8: القطاع أ | E8: أعمال الحفر والتسوية | F8: شركة البنيان المتقدم | G8: مقبول من أول مرة | H8: 0 | I8: تم الفحص وفق الخطة واعتماد العمل دون ملاحظات جوهرية
A9: فحص-0005 | B9: 45673 | C9: 5 | D9: القطاع أ | E9: أعمال الحفر والتسوية | F9: شركة البنيان المتقدم | G9: مقبول من أول مرة | H9: 0 | I9: تم الفحص وفق الخطة واعتماد العمل دون ملاحظات جوهرية
A10: فحص-0006 | B10: 45672 | C10: 6 | D10: القطاع أ | E10: أعمال الحفر والتسوية | F10: شركة البنيان المتقدم | G10: مقبول من أول مرة | H10: 0 | I10: تم الفحص وفق الخطة واعتماد العمل دون ملاحظات جوهرية
A11: فحص-0007 | B11: 45675 | C11: 7 | D11: القطاع أ | E11: أعمال الحفر والتسوية | F11: شركة البنيان المتقدم | G11: مقبول من أول مرة | H11: 0 | I11: تم الفحص وفق الخطة واعتماد العمل دون ملاحظات جوهرية
A12: فحص-0008 | B12: 45676 | C12: 8 | D12: القطاع أ | E12: أعمال الحفر والتسوية | F12: شركة البنيان المتقدم | G12: مقبول من أول مرة | H12: 0 | I12: تم الفحص وفق الخطة واعتماد العمل دون ملاحظات جوهرية
A13: فحص-0009 | B13: 45680 | C13: 9 | D13: القطاع أ | E13: أعمال الحفر والتسوية | F13: شركة البنيان المتقدم | G13: مقبول من أول مرة | H13: 0 | I13: تم الفحص وفق الخطة واعتماد العمل دون ملاحظات جوهرية
A14: فحص-0010 | B14: 45685 | C14: 10 | D14: القطاع أ | E14: أعمال الحفر والتسوية | F14: شركة البنيان المتقدم | G14: مقبول من أول مرة | H14: 0 | I14: تم الفحص وفق الخطة واعتماد العمل دون ملاحظات جوهرية
A15: فحص-0011 | B15: 45689 | C15: 11 | D15: القطاع أ | E15: أعمال الحفر والتسوية | F15: شركة البنيان المتقدم | G15: مقبول من أول مرة | H15: 0 | I15: تم الفحص وفق الخطة واعتماد العمل دون ملاحظات جوهرية
A16: فحص-0012 | B16: 45691 | C16: 12 | D16: القطاع أ | E16: أعمال الحفر والتسوية | F16: شركة البنيان المتقدم | G16: مقبول من أول مرة | H16: 0 | I16: تم الفحص وفق الخطة واعتماد العمل دون ملاحظات جوهرية
... A704: فحص-0700 | B704: 46109 | C704: 120 | D704: القطاع د | E704: الاستلام الابتدائي | F704: فريق الجودة الداخلي | G704: مقبول من أول مرة | H704: 0 | I704: تم الفحص وفق الخطة واعتماد العمل دون ملاحظات جوهرية

Sheet العيوب_والملاحظات
A1: سجل العيوب والملاحظات وعدم المطابقة
A2: يشمل العيوب المفتوحة والمغلقة وتكلفة إعادة العمل التقديرية
A4: رقم العيب | B4: تاريخ الرصد | C4: رقم الفيلا | D4: القطاع | E4: التخصص | F4: وصف الملاحظة | G4: درجة الخطورة | H4: الحالة | I4: الجهة المسؤولة | J4: تاريخ الإغلاق | K4: مدة الإغلاق بالأيام | L4: تكلفة إعادة العمل بالدولار | M4: تكلفة إعادة العمل بالريال السعودي
A5: عيب-0001 | B5: 46022 | C5: 2 | D5: القطاع أ | E5: إنشائي | F5: حاجة إلى تحسين دمك التربة حول القواعد الطرفية | G5: منخفض | H5: مغلق | I5: شركة البنيان المتقدم | J5: 46037 | K5: 15 | L5: 961 | M5: {=L5*3.7} -> 3555.7
A6: عيب-0002 | B6: 45811 | C6: 2 | D6: القطاع أ | E6: موقع | F6: عدم تسوية بعض مناطق الردم طبقًا للمناسيب المعتمدة | G6: منخفض | H6: مغلق | I6: شركة الحدائق والخدمات | J6: 45830 | K6: 19 | L6: 508 | M6: {=L6*3.7} -> 1879.6
A7: عيب-0003 | B7: 45932 | C7: 3 | D7: القطاع أ | E7: إنشائي | F7: حاجة إلى تحسين دمك التربة حول القواعد الطرفية | G7: منخفض | H7: مفتوح | I7: شركة البنيان المتقدم | L7: 942 | M7: {=L7*3.7} -> 3485.4
A8: عيب-0004 | B8: 45921 | C8: 4 | D8: القطاع أ | E8: موقع | F8: عدم تسوية بعض مناطق الردم طبقًا للمناسيب المعتمدة | G8: عال | H8: مفتوح | I8: شركة الحدائق والخدمات | L8: 4354 | M8: {=L8*3.7} -> 16109.8
A9: عيب-0005 | B9: 45731 | C9: 4 | D9: القطاع أ | E9: إنشائي | F9: حاجة إلى تحسين دمك التربة حول القواعد الطرفية | G9: منخفض | H9: مغلق | I9: شركة البنيان المتقدم | J9: 45750 | K9: 19 | L9: 784 | M9: {=L9*3.7} -> 2900.8
A10: عيب-0006 | B10: 45963 | C10: 5 | D10: القطاع أ | E10: موقع | F10: عدم تسوية بعض مناطق الردم طبقًا للمناسيب المعتمدة | G10: متوسط | H10: مفتوح | I10: شركة الحدائق والخدمات | L10: 1479 | M10: {=L10*3.7} -> 5472.3
A11: عيب-0007 | B11: 46010 | C11: 5 | D11: القطاع أ | E11: موقع | F11: عدم تسوية بعض مناطق الردم طبقًا للمناسيب المعتمدة | G11: متوسط | H11: مغلق | I11: شركة الحدائق والخدمات | J11: 46031 | K11: 21 | L11: 1735 | M11: {=L11*3.7} -> 6419.5
A12: عيب-0008 | B12: 45996 | C12: 6 | D12: القطاع أ | E12: إنشائي | F12: حاجة إلى تحسين دمك التربة حول القواعد الطرفية | G12: متوسط | H12: مغلق | I12: شركة البنيان المتقدم | J12: 46009 | K12: 13 | L12: 2469 | M12: {=L12*3.7} -> 9135.3
A13: عيب-0009 | B13: 45761 | C13: 6 | D13: القطاع أ | E13: إنشائي | F13: حاجة إلى تحسين دمك التربة حول القواعد الطرفية | G13: متوسط | H13: مغلق | I13: شركة البنيان المتقدم | J13: 45773 | K13: 12 | L13: 3087 | M13: {=L13*3.7} -> 11421.9
A14: عيب-0010 | B14: 45996 | C14: 7 | D14: القطاع أ | E14: إنشائي | F14: حاجة إلى تحسين دمك التربة حول القواعد الطرفية | G14: عال | H14: مغلق | I14: شركة البنيان المتقدم | J14: 46026 | K14: 30 | L14: 6961 | M14: {=L14*3.7} -> 25755.7
A15: عيب-0011 | B15: 45799 | C15: 7 | D15: القطاع أ | E15: إنشائي | F15: حاجة إلى تحسين دمك التربة حول القواعد الطرفية | G15: متوسط | H15: مغلق | I15: شركة البنيان المتقدم | J15: 45805 | K15: 6 | L15: 2821 | M15: {=L15*3.7} -> 10437.7
A16: عيب-0012 | B16: 45698 | C16: 8 | D16: القطاع أ | E16: إنشائي | F16: حاجة إلى تحسين دمك التربة حول القواعد الطرفية | G16: عال | H16: مفتوح | I16: شركة البنيان المتقدم | L16: 8644 | M16: {=L16*3.7} -> 31982.8
A17: عيب-0013 | B17: 45843 | C17: 8 | D17: القطاع أ | E17: إنشائي | F17: حاجة إلى تحسين دمك التربة حول القواعد الطرفية | G17: متوسط | H17: مفتوح | I17: شركة البنيان المتقدم | L17: 2220 | M17: {=L17*3.7} -> 8214
A18: عيب-0014 | B18: 45862 | C18: 9 | D18: القطاع أ | E18: موقع | F18: عدم تسوية بعض مناطق الردم طبقًا للمناسيب المعتمدة | G18: منخفض | H18: مغلق | I18: شركة الحدائق والخدمات | J18: 45870 | K18: 8 | L18: 411 | M18: {=L18*3.7} -> 1520.7
A19: عيب-0015 | B19: 45950 | C19: 9 | D19: القطاع أ | E19: موقع | F19: عدم تسوية بعض مناطق الردم طبقًا للمناسيب المعتمدة | G19: متوسط | H19: مفتوح | I19: شركة الحدائق والخدمات | L19: 1186 | M19: {=L19*3.7} -> 4388.2
A20: عيب-0016 | B20: 45852 | C20: 10 | D20: القطاع أ | E20: موقع | F20: عدم تسوية بعض مناطق الردم طبقًا للمناسيب المعتمدة | G20: منخفض | H20: مغلق | I20: شركة الحدائق والخدمات | J20: 45859 | K20: 7 | L20: 582 | M20: {=L20*3.7} -> 2153.4
A21: عيب-0017 | B21: 45726 | C21: 10 | D21: القطاع أ | E21: إنشائي | F21: حاجة إلى تحسين دمك التربة حول القواعد الطرفية | G21: منخفض | H21: مغلق | I21: شركة البنيان المتقدم | J21: 45745 | K21: 19 | L21: 915 | M21: {=L21*3.7} -> 3385.5
A22: عيب-0018 | B22: 45978 | C22: 11 | D22: القطاع أ | E22: إنشائي | F22: حاجة إلى تحسين دمك التربة حول القواعد الطرفية | G22: منخفض | H22: مغلق | I22: شركة البنيان المتقدم | J22: 45982 | K22: 4 | L22: 790 | M22: {=L22*3.7} -> 2923
A23: عيب-0019 | B23: 45769 | C23: 11 | D23: القطاع أ | E23: موقع | F23: عدم تسوية بعض مناطق الردم طبقًا للمناسيب المعتمدة | G23: منخفض | H23: مغلق | I23: شركة الحدائق والخدمات | J23: 45787 | K23: 18 | L23: 525 | M23: {=L23*3.7} -> 1942.5
A24: عيب-0020 | B24: 45841 | C24: 13 | D24: القطاع أ | E24: إنشائي | F24: حاجة إلى تحسين دمك التربة حول القواعد الطرفية | G24: منخفض | H24: مغلق | I24: شركة البنيان المتقدم | J24: 45854 | K24: 13 | L24: 888 | M24: {=L24*3.7} -> 3285.6
A25: عيب-0021 | B25: 45779 | C25: 14 | D25: القطاع أ | E25: إنشائي | F25: حاجة إلى تحسين دمك التربة حول القواعد الطرفية | G25: منخفض | H25: مغلق | I25: شركة البنيان المتقدم | J25: 45785 | K25: 6 | L25: 989 | M25: {=L25*3.7} -> 3659.3
A26: عيب-0022 | B26: 45990 | C26: 16 | D26: القطاع أ | E26: إنشائي | F26: حاجة إلى تحسين دمك التربة حول القواعد الطرفية | G26: عال | H26: مغلق | I26: شركة البنيان المتقدم | J26: 46020 | K26: 30 | L26: 7059 | M26: {=L26*3.7} -> 26118.3
A27: عيب-0023 | B27: 45811 | C27: 18 | D27: القطاع أ | E27: إنشائي | F27: حاجة إلى تحسين دمك التربة حول القواعد الطرفية | G27: منخفض | H27: مغلق | I27: شركة البنيان المتقدم | J27: 45823 | K27: 12 | L27: 1000 | M27: {=L27*3.7} -> 3700
A28: عيب-0024 | B28: 45750 | C28: 20 | D28: القطاع أ | E28: موقع | F28: عدم تسوية بعض مناطق الردم طبقًا للمناسيب المعتمدة | G28: متوسط | H28: مغلق | I28: شركة الحدائق والخدمات | J28: 45765 | K28: 15 | L28: 1443 | M28: {=L28*3.7} -> 5339.1
A29: عيب-0025 | B29: 45921 | C29: 21 | D29: القطاع أ | E29: إنشائي | F29: ملاحظات على تثبيت الأشاير قبل الصب | G29: منخفض | H29: مفتوح | I29: شركة البنيان المتقدم | L29: 1023 | M29: {=L29*3.7} -> 3785.1
A30: عيب-0026 | B30: 46003 | C30: 21 | D30: القطاع أ | E30: موقع | F30: تجمع مياه مؤقت قرب حفريات الخدمة | G30: عال | H30: مغلق | I30: شركة الحدائق والخدمات | J30: 46024 | K30: 21 | L30: 4218 | M30: {=L30*3.7} -> 15606.6
A31: عيب-0027 | B31: 45981 | C31: 21 | D31: القطاع أ | E31: إنشائي | F31: تفاوت محدود في أغطية التسليح بالقواعد | G31: منخفض | H31: مفتوح | I31: شركة البنيان المتقدم | L31: 774 | M31: {=L31*3.7} -> 2863.8
A32: عيب-0028 | B32: 45793 | C32: 22 | D32: القطاع أ | E32: إنشائي | F32: ملاحظات على تثبيت الأشاير قبل الصب | G32: متوسط | H32: مغلق | I32: شركة البنيان المتقدم | J32: 45799 | K32: 6 | L32: 2781 | M32: {=L32*3.7} -> 10289.7
A33: عيب-0029 | B33: 45875 | C33: 22 | D33: القطاع أ | E33: إنشائي | F33: ملاحظات على تثبيت الأشاير قبل الصب | G33: حرج | H33: مغلق | I33: شركة البنيان المتقدم | J33: 45887 | K33: 12 | L33: 18340 | M33: {=L33*3.7} -> 67858
A34: عيب-0030 | B34: 45729 | C34: 22 | D34: القطاع أ | E34: إنشائي | F34: تفاوت محدود في أغطية التسليح بالقواعد | G34: منخفض | H34: مغلق | I34: شركة البنيان المتقدم | J34: 45735 | K34: 6 | L34: 923 | M34: {=L34*3.7} -> 3415.1
A35: عيب-0031 | B35: 45987 | C35: 23 | D35: القطاع أ | E35: إنشائي | F35: ملاحظات على تثبيت الأشاير قبل الصب | G35: منخفض | H35: مفتوح | I35: شركة البنيان المتقدم | L35: 857 | M35: {=L35*3.7} -> 3170.9
A36: عيب-0032 | B36: 45796 | C36: 24 | D36: القطاع أ | E36: إنشائي | F36: تفاوت محدود في أغطية التسليح بالقواعد | G36: منخفض | H36: مفتوح | I36: شركة البنيان المتقدم | L36: 764 | M36: {=L36*3.7} -> 2826.8
A37: عيب-0033 | B37: 46034 | C37: 24 | D37: القطاع أ | E37: موقع | F37: تجمع مياه مؤقت قرب حفريات الخدمة | G37: عال | H37: مفتوح | I37: شركة الحدائق والخدمات | L37: 3312 | M37: {=L37*3.7} -> 12254.4
A38: عيب-0034 | B38: 46029 | C38: 25 | D38: القطاع أ | E38: موقع | F38: تجمع مياه مؤقت قرب حفريات الخدمة | G38: متوسط | H38: مفتوح | I38: شركة الحدائق والخدمات | L38: 1401 | M38: {=L38*3.7} -> 5183.7
A39: عيب-0035 | B39: 45940 | C39: 26 | D39: القطاع أ | E39: إنشائي | F39: تفاوت محدود في أغطية التسليح بالقواعد | G39: عال | H39: مفتوح | I39: شركة البنيان المتقدم | L39: 8652 | M39: {=L39*3.7} -> 32012.4
A40: عيب-0036 | B40: 45915 | C40: 27 | D40: القطاع أ | E40: إنشائي | F40: ملاحظات على تثبيت الأشاير قبل الصب | G40: متوسط | H40: مغلق | I40: شركة البنيان المتقدم | J40: 45926 | K40: 11 | L40: 2910 | M40: {=L40*3.7} -> 10767
A41: عيب-0037 | B41: 45883 | C41: 27 | D41: القطاع أ | E41: إنشائي | F41: تفاوت محدود في أغطية التسليح بالقواعد | G41: متوسط | H41: مغلق | I41: شركة البنيان المتقدم | J41: 45902 | K41: 19 | L41: 2530 | M41: {=L41*3.7} -> 9361
...

Sheet المواد_والكميات
A1: متابعة المواد والكميات التراكمية
A2: الكميات المخططة والمستلمة والمصروفة والمستخدمة الفعلية حتى تاريخ التقرير
A4: المادة | B4: الوحدة | C4: الكمية المخططة التراكمية | D4: الكمية المستلمة | E4: الكمية المصروفة | F4: الكمية المستخدمة فعليًا | G4: الهدر | H4: نسبة الهدر | I4: النسبة المستهدفة | J4: حالة الأداء | K4: سعر الوحدة بالدولار | L4: سعر الوحدة بالريال | M4: تكلفة الهدر بالدولار | N4: تكلفة الهدر بالريال
A5: خرسانة جاهزة | B5: م3 | C5: 24600 | D5: 25100 | E5: 24950 | F5: 24215 | G5: 735 | H5: 0.029458918 | I5: 0.03 | J5: ضمن الهدف | K5: 320 | L5: {=K5*3.7} -> 1184 | M5: 235200 | N5: {=M5*3.7} -> 870240
A6: حديد تسليح | B6: طن | C6: 3180 | D6: 3250 | E6: 3210 | F6: 3132 | G6: 78 | H6: 0.024299065 | I6: 0.025 | J6: ضمن الهدف | K6: 3300 | L6: {=K6*3.7} -> 12210 | M6: 257400 | N6: {=M6*3.7} -> 952380
A7: بلوك إسمنتي | B7: م2 | C7: 146000 | D7: 149200 | E7: 147500 | F7: 141850 | G7: 5650 | H7: 0.038305085 | I7: 0.04 | J7: ضمن الهدف | K7: 48 | L7: {=K7*3.7} -> 177.6 | M7: 271200 | N7: {=M7*3.7} -> 1003440
A8: عزل مائي وحراري | B8: م2 | C8: 31400 | D8: 32100 | E8: 31900 | F8: 30980 | G8: 920 | H8: 0.028840125 | I8: 0.03 | J8: ضمن الهدف | K8: 38 | L8: {=K8*3.7} -> 140.6 | M8: 34960 | N8: {=M8*3.7} -> 129352
A9: لياسة ومحارة | B9: م2 | C9: 118000 | D9: 120400 | E9: 119100 | F9: 113980 | G9: 5120 | H9: 0.042989085 | I9: 0.05 | J9: ضمن الهدف | K9: 24 | L9: {=K9*3.7} -> 88.8 | M9: 122880 | N9: {=M9*3.7} -> 454656
A10: بلاط وسيراميك | B10: م2 | C10: 52600 | D10: 53900 | E10: 53100 | F10: 50760 | G10: 2340 | H10: 0.044067797 | I10: 0.04 | J10: بحاجة إلى تحسين | K10: 72 | L10: {=K10*3.7} -> 266.4 | M10: 168480 | N10: {=M10*3.7} -> 623376
A11: دهانات | B11: م2 | C11: 81700 | D11: 83000 | E11: 82500 | F11: 77880 | G11: 4620 | H11: 0.056 | I11: 0.06 | J11: ضمن الهدف | K11: 18 | L11: {=K11*3.7} -> 66.6 | M11: 83160 | N11: {=M11*3.7} -> 307692
A12: كوابل كهربائية | B12: م.ط | C12: 196000 | D12: 198800 | E12: 197400 | F12: 193630 | G12: 3770 | H12: 0.019098278 | I12: 0.02 | J12: ضمن الهدف | K12: 14 | L12: {=K12*3.7} -> 51.8 | M12: 52780 | N12: {=M12*3.7} -> 195286
A13: مواسير صحية وميكانيكية | B13: م.ط | C13: 128500 | D13: 130200 | E13: 129600 | F13: 126840 | G13: 2760 | H13: 0.021296296 | I13: 0.02 | J13: بحاجة إلى تحسين | K13: 26 | L13: {=K13*3.7} -> 96.2 | M13: 71760 | N13: {=M13*3.7} -> 265512

Sheet هدر_الموارد
A1: تقرير هدر الموارد وكفاءة الاستخدام
A2: يربط بين هدر المواد والوقت والمعدات وتكلفة الهدر المباشر التراكمية
A4: فئة المورد | B4: المورد | C4: الوحدة | D4: المصروف أو الفعلي | E4: المستخدم المنتج | F4: الهدر | G4: نسبة الهدر | H4: النسبة المستهدفة | I4: سعر الوحدة بالدولار | J4: سعر الوحدة بالدولار | K4: تكلفة الهدر بالدولار | L4: تكلفة الهدر بالدولار | M4: ملاحظة الإدارة
A5: مواد | B5: خرسانة جاهزة | C5: م3 | D5: 24950 | E5: 24215 | F5: 735 | G5: 0.029458918 | H5: 0.03 | I5: 320 | J5: {=I5*3.7} -> 1184 | K5: 235200 | L5: {=K5*3.7} -> 870240 | M5: يرتبط مباشرة بالصرف الفعلي في الموقع
A6: مواد | B6: حديد تسليح | C6: طن | D6: 3210 | E6: 3132 | F6: 78 | G6: 0.024299065 | H6: 0.025 | I6: 3300 | J6: {=I6*3.7} -> 12210 | K6: 257400 | L6: {=K6*3.7} -> 952380 | M6: يرتبط مباشرة بالصرف الفعلي في الموقع
A7: مواد | B7: بلوك إسمنتي | C7: م2 | D7: 147500 | E7: 141850 | F7: 5650 | G7: 0.038305085 | H7: 0.04 | I7: 48 | J7: {=I7*3.7} -> 177.6 | K7: 271200 | L7: {=K7*3.7} -> 1003440 | M7: يرتبط مباشرة بالصرف الفعلي في الموقع
A8: مواد | B8: عزل مائي وحراري | C8: م2 | D8: 31900 | E8: 30980 | F8: 920 | G8: 0.028840125 | H8: 0.03 | I8: 38 | J8: {=I8*3.7} -> 140.6 | K8: 34960 | L8: {=K8*3.7} -> 129352 | M8: يرتبط مباشرة بالصرف الفعلي في الموقع
A9: مواد | B9: لياسة ومحارة | C9: م2 | D9: 119100 | E9: 113980 | F9: 5120 | G9: 0.042989085 | H9: 0.05 | I9: 24 | J9: {=I9*3.7} -> 88.8 | K9: 122880 | L9: {=K9*3.7} -> 454656 | M9: يرتبط مباشرة بالصرف الفعلي في الموقع
A10: مواد | B10: بلاط وسيراميك | C10: م2 | D10: 53100 | E10: 50760 | F10: 2340 | G10: 0.044067797 | H10: 0.04 | I10: 72 | J10: {=I10*3.7} -> 266.4 | K10: 168480 | L10: {=K10*3.7} -> 623376 | M10: يرتبط مباشرة بالصرف الفعلي في الموقع
A11: مواد | B11: دهانات | C11: م2 | D11: 82500 | E11: 77880 | F11: 4620 | G11: 0.056 | H11: 0.06 | I11: 18 | J11: {=I11*3.7} -> 66.6 | K11: 83160 | L11: {=K11*3.7} -> 307692 | M11: يرتبط مباشرة بالصرف الفعلي في الموقع
A12: مواد | B12: كوابل كهربائية | C12: م.ط | D12: 197400 | E12: 193630 | F12: 3770 | G12: 0.019098278 | H12: 0.02 | I12: 14 | J12: {=I12*3.7} -> 51.8 | K12: 52780 | L12: {=K12*3.7} -> 195286 | M12: يرتبط مباشرة بالصرف الفعلي في الموقع
A13: مواد | B13: مواسير صحية وميكانيكية | C13: م.ط | D13: 129600 | E13: 126840 | F13: 2760 | G13: 0.021296296 | H13: 0.02 | I13: 26 | J13: {=I13*3.7} -> 96.2 | K13: 71760 | L13: {=K13*3.7} -> 265512 | M13: يرتبط مباشرة بالصرف الفعلي في الموقع
A14: وقت | B14: ساعات العمل | C14: ساعة | D14: 193500 | E14: 179200 | F14: 14300 | G14: 0.073901809 | H14: 0.08 | I14: 42 | J14: {=I14*3.7} -> 155.4 | K14: 600600 | L14: {=K14*3.7} -> 2222220 | M14: الهدر ناتج عن إعادة عمل وانتظار وتداخل فرق
A15: معدات | B15: معدات الرفع | C15: ساعة | D15: 13050 | E15: 11860 | F15: 1190 | G15: 0.091187739 | H15: 0.07 | I15: 185 | J15: {=I15*3.7} -> 684.5 | K15: 220150 | L15: {=K15*3.7} -> 814555 | M15: زيادة تشغيل عن الحاجة بسبب إعادة الجدولة
A16: معدات | B16: مولدات ومضخات | C16: ساعة | D16: 9480 | E16: 8935 | F16: 545 | G16: 0.057489451 | H16: 0.06 | I16: 96 | J16: {=I16*3.7} -> 355.2 | K16: 52320 | L16: {=K16*3.7} -> 193584 | M16: مستوى الأداء مقبول لكنه يحتاج متابعة
A19: ملخص هدر الموارد
A20: إجمالي تكلفة هدر المواد | B20: {=SUM(K5:K13)} -> 1297820
A21: إجمالي تكلفة هدر الوقت والمعدات | B21: {=SUM(K14:K16)} -> 873070
A22: إجمالي تكلفة إعادة العمل من سجل العيوب | B22: 1070381
A23: إجمالي تكلفة الهدر المباشر | B23: {=B20+B21} -> 2170890
A24: نسبة الهدر المباشر إلى قيمة الأعمال المنفذة | B24: {=B23/154800000} -> 0.014023837
A25: النسبة المستهدفة لهدر الموارد المباشر | B25: 0.05

Sheet أداء_المقاولين
A1: تقييم أداء المقاولين الرئيسيين من منظور الجودة
A2: التقييم يعتمد على الفحوصات، العيوب، تكلفة إعادة العمل، ونسبة الهدر المرتبطة بكل حزمة
A4: المقاول | B4: نطاق العمل | C4: عدد الفحوصات | D4: قبول من أول مرة | E4: نسبة القبول | F4: العيوب المفتوحة | G4: تكلفة إعادة العمل بالدولار | H4: تكلفة إعادة العمل بالريال | I4: نسبة الهدر المرتبطة | J4: الالتزام الزمني | K4: التقييم النهائي
A5: شركة البنيان المتقدم | B5: الحفر والأساسات والهيكل | C5: {=COUNTIF('الفحوصات_والاختبارات'!$F$5:$F$704,A5)} -> 484 | D5: {=_xlfn.COUNTIFS('الفحوصات_والاختبارات'!$F$5:$F$704,A5,'الفحوصات_والاختبارات'!$G$5:$G$704,"مقبول من أول مرة")} -> 430 | E5: {=_xlfn.IFERROR(D5/C5,0)} -> 0.88842975 | F5: 25 | G5: 229329 | H5: {=G5*3.7} -> 848517.3 | I5: 0.029 | J5: 0.91 | K5: {=ROUND(((E5*0.5)+((1-MIN(1,F5/60))*0.15)+((1-MIN(1,I5/0.08))*0.15)+(J5*0.2))*100,1)} -> 80.9
A6: شركة الأنظمة المتكاملة | B6: الأعمال الكهربائية والميكانيكية | C6: {=COUNTIF('الفحوصات_والاختبارات'!$F$5:$F$704,A6)} -> 60 | D6: {=_xlfn.COUNTIFS('الفحوصات_والاختبارات'!$F$5:$F$704,A6,'الفحوصات_والاختبارات'!$G$5:$G$704,"مقبول من أول مرة")} -> 48 | E6: {=_xlfn.IFERROR(D6/C6,0)} -> 0.8 | F6: 21 | G6: 245535 | H6: {=G6*3.7} -> 908479.5 | I6: 0.02 | J6: 0.88 | K6: {=ROUND(((E6*0.5)+((1-MIN(1,F6/60))*0.15)+((1-MIN(1,I6/0.08))*0.15)+(J6*0.2))*100,1)} -> 78.6
A7: شركة الإتقان للتشطيبات | B7: التشطيبات الداخلية والخارجية | C7: {=COUNTIF('الفحوصات_والاختبارات'!$F$5:$F$704,A7)} -> 88 | D7: {=_xlfn.COUNTIFS('الفحوصات_والاختبارات'!$F$5:$F$704,A7,'الفحوصات_والاختبارات'!$G$5:$G$704,"مقبول من أول مرة")} -> 76 | E7: {=_xlfn.IFERROR(D7/C7,0)} -> 0.86363636 | F7: 15 | G7: 225378 | H7: {=G7*3.7} -> 833898.6 | I7: 0.049 | J7: 0.86 | K7: {=ROUND(((E7*0.5)+((1-MIN(1,F7/60))*0.15)+((1-MIN(1,I7/0.08))*0.15)+(J7*0.2))*100,1)} -> 77.4
A8: شركة العزل والبنية الحديثة | B8: العزل ومعالجات الإغلاق | C8: {=COUNTIF('الفحوصات_والاختبارات'!$F$5:$F$704,A8)} -> 44 | D8: {=_xlfn.COUNTIFS('الفحوصات_والاختبارات'!$F$5:$F$704,A8,'الفحوصات_والاختبارات'!$G$5:$G$704,"مقبول من أول مرة")} -> 37 | E8: {=_xlfn.IFERROR(D8/C8,0)} -> 0.84090909 | F8: 27 | G8: 269262 | H8: {=G8*3.7} -> 996269.4 | I8: 0.029 | J8: 0.89 | K8: {=ROUND(((E8*0.5)+((1-MIN(1,F8/60))*0.15)+((1-MIN(1,I8/0.08))*0.15)+(J8*0.2))*100,1)} -> 77.7

Sheet المخاطر
A1: سجل المخاطر المرتبطة بالجودة
A2: أهم المخاطر الفنية والتشغيلية ذات التأثير على جودة المشروع
A4: رقم الخطر | B4: وصف الخطر | C4: التصنيف | D4: الاحتمال | E4: الأثر | F4: درجة الخطر | G4: إجراء المعالجة | H4: الحالة
A5: خطر-01 | B5: تأخر اعتماد بعض المواد البديلة يؤدي لإعادة ترتيب الجدول | C5: توريد | D5: 3 | E5: 4 | F5: {=D5*E5} -> 12 | G5: منع أي بديل غير معتمد وإقفال قرار الشراء قبل التنفيذ بأسبوعين | H5: قيد المتابعة
A6: خطر-02 | B6: تعارضات بين التمديدات المعمارية والكهروميكانيكية | C6: تصميم | D6: 3 | E6: 5 | F6: {=D6*E6} -> 15 | G6: مراجعة تنسيقية أسبوعية للرسومات التنفيذية | H6: قيد المتابعة
A7: خطر-03 | B7: ارتفاع هدر البلوك واللياسة بسبب تعديلات ميدانية | C7: هدر موارد | D7: 4 | E7: 4 | F7: {=D7*E7} -> 16 | G7: ضبط العمل قبل التنفيذ ومنع التكسير غير المعتمد | H7: مرتفع
A8: خطر-04 | B8: ضعف نظافة الموقع يؤثر على جودة التشطيبات النهائية | C8: موقع | D8: 3 | E8: 3 | F8: {=D8*E8} -> 9 | G8: خطة تنظيف يومية ومناطق تجميع واضحة للمخلفات | H8: قيد المتابعة
A9: خطر-05 | B9: إعادة عمل في العزل بسبب اختراقات خدمات غير مغلقة | C9: عزل | D9: 3 | E9: 4 | F9: {=D9*E9} -> 12 | G9: فحص نقاط الاختراق قبل وبعد الإغلاق | H9: قيد المعالجة
A10: خطر-06 | B10: انخفاض معدل القبول من أول مرة في التشطيبات | C10: تنفيذ | D10: 4 | E10: 4 | F10: {=D10*E10} -> 16 | G10: تعزيز إشراف ما قبل الفحص وقوائم تحقق للغرف النموذجية | H10: مرتفع
A11: خطر-07 | B11: تأخر إغلاق العيوب المفتوحة في الوحدات المكتملة | C11: استلام | D11: 2 | E11: 4 | F11: {=D11*E11} -> 8 | G11: تحديد مدة إغلاق قصوى وربطها بخطة تسليم أسبوعية | H11: قيد المتابعة
A12: خطر-08 | B12: إجهاد فرق العمل نتيجة تداخل الأنشطة في القطاعات النهائية | C12: إنتاجية | D12: 3 | E12: 3 | F12: {=D12*E12} -> 9 | G12: إعادة موازنة الموارد بين القطاعات | H12: قيد المتابعة
A13: خطر-09 | B13: عدم اكتمال وثائق التسليم لبعض الوحدات | C13: وثائق | D13: 2 | E13: 5 | F13: {=D13*E13} -> 10 | G13: مراجعة أسبوعية لحزمة التسليم لكل فيلا | H13: قيد المعالجة
A14: خطر-10 | B14: عدم ثبات جودة المورد لبعض التشطيبات الحساسة | C14: موردون | D14: 2 | E14: 4 | F14: {=D14*E14} -> 8 | G14: اعتماد عينات مسبقة ومراجعة دفعات الاستلام | H14: منخفض

Sheet الاستلام_والتسليم
A1: متابعة الاستلام المرحلي والنهائي
A2: تجميع جاهزية الوحدات للتسليم بناءً على المرحلة، العيوب المفتوحة، وجاهزية الوثائق والأنظمة
A4: رقم الفيلا | B4: القطاع | C4: المرحلة الحالية | D4: نسبة الإنجاز | E4: العيوب المفتوحة | F4: جاهزية الوثائق | G4: جاهزية الأنظمة | H4: حالة التسليم | I4: تاريخ التسليم المخطط | J4: تاريخ التسليم المتوقع
A5: 1 | B5: القطاع أ | C5: حفر | D5: 0.1189 | E5: 0 | F5: {=IF(C5="مكتملة",0.95,IF(C5="تشطيبات",0.78,IF(C5="كهروميكانيك",0.55,IF(C5="هيكل",0.35,IF(C5="أساسات",0.22,0.12)))))} -> 0.12 | G5: {=IF(C5="مكتملة",0.96,IF(C5="تشطيبات",0.88,IF(C5="كهروميكانيك",0.72,IF(C5="هيكل",0.44,IF(C5="أساسات",0.2,0.08)))))} -> 0.08 | H5: {=IF(AND(C5="مكتملة",E5<=3,F5>=0.9,G5>=0.9),"جاهزة للاستلام الابتدائي",IF(OR(C5="تشطيبات",C5="مكتملة"),"قيد التجهيز","غير جاهزة"))} -> غير جاهزة | I5: 46052 | J5: 46135
A6: 2 | B6: القطاع أ | C6: حفر | D6: 0.1423 | E6: 0 | F6: {=IF(C6="مكتملة",0.95,IF(C6="تشطيبات",0.78,IF(C6="كهروميكانيك",0.55,IF(C6="هيكل",0.35,IF(C6="أساسات",0.22,0.12)))))} -> 0.12 | G6: {=IF(C6="مكتملة",0.96,IF(C6="تشطيبات",0.88,IF(C6="كهروميكانيك",0.72,IF(C6="هيكل",0.44,IF(C6="أساسات",0.2,0.08)))))} -> 0.08 | H6: {=IF(AND(C6="مكتملة",E6<=3,F6>=0.9,G6>=0.9),"جاهزة للاستلام الابتدائي",IF(OR(C6="تشطيبات",C6="مكتملة"),"قيد التجهيز","غير جاهزة"))} -> غير جاهزة | I6: 46055 | J6: 46148
A7: 3 | B7: القطاع أ | C7: حفر | D7: 0.1353 | E7: 1 | F7: {=IF(C7="مكتملة",0.95,IF(C7="تشطيبات",0.78,IF(C7="كهروميكانيك",0.55,IF(C7="هيكل",0.35,IF(C7="أساسات",0.22,0.12)))))} -> 0.12 | G7: {=IF(C7="مكتملة",0.96,IF(C7="تشطيبات",0.88,IF(C7="كهروميكانيك",0.72,IF(C7="هيكل",0.44,IF(C7="أساسات",0.2,0.08)))))} -> 0.08 | H7: {=IF(AND(C7="مكتملة",E7<=3,F7>=0.9,G7>=0.9),"جاهزة للاستلام الابتدائي",IF(OR(C7="تشطيبات",C7="مكتملة"),"قيد التجهيز","غير جاهزة"))} -> غير جاهزة | I7: 46058 | J7: 46165
A8: 4 | B8: القطاع أ | C8: حفر | D8: 0.1419 | E8: 1 | F8: {=IF(C8="مكتملة",0.95,IF(C8="تشطيبات",0.78,IF(C8="كهروميكانيك",0.55,IF(C8="هيكل",0.35,IF(C8="أساسات",0.22,0.12)))))} -> 0.12 | G8: {=IF(C8="مكتملة",0.96,IF(C8="تشطيبات",0.88,IF(C8="كهروميكانيك",0.72,IF(C8="هيكل",0.44,IF(C8="أساسات",0.2,0.08)))))} -> 0.08 | H8: {=IF(AND(C8="مكتملة",E8<=3,F8>=0.9,G8>=0.9),"جاهزة للاستلام الابتدائي",IF(OR(C8="تشطيبات",C8="مكتملة"),"قيد التجهيز","غير جاهزة"))} -> غير جاهزة | I8: 46061 | J8: 46147
A9: 5 | B9: القطاع أ | C9: حفر | D9: 0.1199 | E9: 1 | F9: {=IF(C9="مكتملة",0.95,IF(C9="تشطيبات",0.78,IF(C9="كهروميكانيك",0.55,IF(C9="هيكل",0.35,IF(C9="أساسات",0.22,0.12)))))} -> 0.12 | G9: {=IF(C9="مكتملة",0.96,IF(C9="تشطيبات",0.88,IF(C9="كهروميكانيك",0.72,IF(C9="هيكل",0.44,IF(C9="أساسات",0.2,0.08)))))} -> 0.08 | H9: {=IF(AND(C9="مكتملة",E9<=3,F9>=0.9,G9>=0.9),"جاهزة للاستلام الابتدائي",IF(OR(C9="تشطيبات",C9="مكتملة"),"قيد التجهيز","غير جاهزة"))} -> غير جاهزة | I9: 46064 | J9: 46156
A10: 6 | B10: القطاع أ | C10: حفر | D10: 0.1271 | E10: 0 | F10: {=IF(C10="مكتملة",0.95,IF(C10="تشطيبات",0.78,IF(C10="كهروميكانيك",0.55,IF(C10="هيكل",0.35,IF(C10="أساسات",0.22,0.12)))))} -> 0.12 | G10: {=IF(C10="مكتملة",0.96,IF(C10="تشطيبات",0.88,IF(C10="كهروميكانيك",0.72,IF(C10="هيكل",0.44,IF(C10="أساسات",0.2,0.08)))))} -> 0.08 | H10: {=IF(AND(C10="مكتملة",E10<=3,F10>=0.9,G10>=0.9),"جاهزة للاستلام الابتدائي",IF(OR(C10="تشطيبات",C10="مكتملة"),"قيد التجهيز","غير جاهزة"))} -> غير جاهزة | I10: 46067 | J10: 46145
A11: 7 | B11: القطاع أ | C11: حفر | D11: 0.1333 | E11: 0 | F11: {=IF(C11="مكتملة",0.95,IF(C11="تشطيبات",0.78,IF(C11="كهروميكانيك",0.55,IF(C11="هيكل",0.35,IF(C11="أساسات",0.22,0.12)))))} -> 0.12 | G11: {=IF(C11="مكتملة",0.96,IF(C11="تشطيبات",0.88,IF(C11="كهروميكانيك",0.72,IF(C11="هيكل",0.44,IF(C11="أساسات",0.2,0.08)))))} -> 0.08 | H11: {=IF(AND(C11="مكتملة",E11<=3,F11>=0.9,G11>=0.9),"جاهزة للاستلام الابتدائي",IF(OR(C11="تشطيبات",C11="مكتملة"),"قيد التجهيز","غير جاهزة"))} -> غير جاهزة | I11: 46070 | J11: 46155
A12: 8 | B12: القطاع أ | C12: حفر | D12: 0.1079 | E12: 2 | F12: {=IF(C12="مكتملة",0.95,IF(C12="تشطيبات",0.78,IF(C12="كهروميكانيك",0.55,IF(C12="هيكل",0.35,IF(C12="أساسات",0.22,0.12)))))} -> 0.12 | G12: {=IF(C12="مكتملة",0.96,IF(C12="تشطيبات",0.88,IF(C12="كهروميكانيك",0.72,IF(C12="هيكل",0.44,IF(C12="أساسات",0.2,0.08)))))} -> 0.08 | H12: {=IF(AND(C12="مكتملة",E12<=3,F12>=0.9,G12>=0.9),"جاهزة للاستلام الابتدائي",IF(OR(C12="تشطيبات",C12="مكتملة"),"قيد التجهيز","غير جاهزة"))} -> غير جاهزة | I12: 46073 | J12: 46191
A13: 9 | B13: القطاع أ | C13: حفر | D13: 0.141 | E13: 1 | F13: {=IF(C13="مكتملة",0.95,IF(C13="تشطيبات",0.78,IF(C13="كهروميكانيك",0.55,IF(C13="هيكل",0.35,IF(C13="أساسات",0.22,0.12)))))} -> 0.12 | G13: {=IF(C13="مكتملة",0.96,IF(C13="تشطيبات",0.88,IF(C13="كهروميكانيك",0.72,IF(C13="هيكل",0.44,IF(C13="أساسات",0.2,0.08)))))} -> 0.08 | H13: {=IF(AND(C13="مكتملة",E13<=3,F13>=0.9,G13>=0.9),"جاهزة للاستلام الابتدائي",IF(OR(C13="تشطيبات",C13="مكتملة"),"قيد التجهيز","غير جاهزة"))} -> غير جاهزة | I13: 46076 | J13: 46187
A14: 10 | B14: القطاع أ | C14: حفر | D14: 0.1072 | E14: 0 | F14: {=IF(C14="مكتملة",0.95,IF(C14="تشطيبات",0.78,IF(C14="كهروميكانيك",0.55,IF(C14="هيكل",0.35,IF(C14="أساسات",0.22,0.12)))))} -> 0.12 | G14: {=IF(C14="مكتملة",0.96,IF(C14="تشطيبات",0.88,IF(C14="كهروميكانيك",0.72,IF(C14="هيكل",0.44,IF(C14="أساسات",0.2,0.08)))))} -> 0.08 | H14: {=IF(AND(C14="مكتملة",E14<=3,F14>=0.9,G14>=0.9),"جاهزة للاستلام الابتدائي",IF(OR(C14="تشطيبات",C14="مكتملة"),"قيد التجهيز","غير جاهزة"))} -> غير جاهزة | I14: 46079 | J14: 46196
A15: 11 | B15: القطاع أ | C15: حفر | D15: 0.0915 | E15: 0 | F15: {=IF(C15="مكتملة",0.95,IF(C15="تشطيبات",0.78,IF(C15="كهروميكانيك",0.55,IF(C15="هيكل",0.35,IF(C15="أساسات",0.22,0.12)))))} -> 0.12 | G15: {=IF(C15="مكتملة",0.96,IF(C15="تشطيبات",0.88,IF(C15="كهروميكانيك",0.72,IF(C15="هيكل",0.44,IF(C15="أساسات",0.2,0.08)))))} -> 0.08 | H15: {=IF(AND(C15="مكتملة",E15<=3,F15>=0.9,G15>=0.9),"جاهزة للاستلام الابتدائي",IF(OR(C15="تشطيبات",C15="مكتملة"),"قيد التجهيز","غير جاهزة"))} -> غير جاهزة | I15: 46082 | J15: 46177
A16: 12 | B16: القطاع أ | C16: حفر | D16: 0.1488 | E16: 0 | F16: {=IF(C16="مكتملة",0.95,IF(C16="تشطيبات",0.78,IF(C16="كهروميكانيك",0.55,IF(C16="هيكل",0.35,IF(C16="أساسات",0.22,0.12)))))} -> 0.12 | G16: {=IF(C16="مكتملة",0.96,IF(C16="تشطيبات",0.88,IF(C16="كهروميكانيك",0.72,IF(C16="هيكل",0.44,IF(C16="أساسات",0.2,0.08)))))} -> 0.08 | H16: {=IF(AND(C16="مكتملة",E16<=3,F16>=0.9,G16>=0.9),"جاهزة للاستلام الابتدائي",IF(OR(C16="تشطيبات",C16="مكتملة"),"قيد التجهيز","غير جاهزة"))} -> غير جاهزة | I16: 46085 | J16: 46196
... A124: 120 | B124: القطاع د | C124: مكتملة | D124: 0.9739 | E124: 0 | F124: {=IF(C124="مكتملة",0.95,IF(C124="تشطيبات",0.78,IF(C124="كهروميكانيك",0.55,IF(C124="هيكل",0.35,IF(C124="أساسات",0.22,0.12)))))} -> 0.95 | G124: {=IF(C124="مكتملة",0.96,IF(C124="تشطيبات",0.88,IF(C124="كهروميكانيك",0.72,IF(C124="هيكل",0.44,IF(C124="أساسات",0.2,0.08)))))} -> 0.96 | H124: {=IF(AND(C124="مكتملة",E124<=3,F124>=0.9,G124>=0.9),"جاهزة للاستلام الابتدائي",IF(OR(C124="تشطيبات",C124="مكتملة"),"قيد التجهيز","غير جاهزة"))} -> جاهزة للاستلام الابتدائي | I124: 46469 | J124: 46467

Sheet قوائم
A1: قوائم الاستخدام والتحقق
A2: هذه القوائم تغذي القوائم المنسدلة في الجداول التشغيلية
A4: حالات الفحص | B4: حالات العيوب | C4: درجات الخطورة | D4: حالات التسليم | E4: حالة الأداء | F4: نوع القياس
A5: مقبول من أول مرة | B5: مفتوح | C5: منخفض | D5: غير جاهزة | E5: ضمن الهدف | F5: أعلى أفضل
A6: مقبول بعد إعادة | B6: مغلق | C6: متوسط | D6: قيد التجهيز | E6: أعلى من الهدف | F6: أقل أفضل
A7: مرفوض | C7: عال | D7: جاهزة للاستلام الابتدائي | E7: بحاجة إلى تحسين
C8: حرج | D8: مستلمة ابتدائيًا | E8: حرج
